Workbook

Sheet VERİ BANKASI
A1: S.N. | B1: MASRAF CİNSİ SEÇİNİZ | C1: KDV ORANI SEÇİNİZ | D1: YIL SEÇİNİZ | E1: AY SEÇİNİZ | F1: MASRAF MERKEZİ SEÇİNİZ | G1: İL SEÇİNİZ | H1: İLGİLİ SEÇİNİZ | I1: ÖDEME TÜRÜ SEÇİNİZ | J1: ARAÇ PLAKA SEÇİNİZ | K1: FİRMA SEÇİNİZ | L1: GÜN ARALIĞI SEÇİNİZ | M1: SATICI KODU | N1: SATICI SEÇİNİZ
A2: 1 | B2: ARAÇ YAKIT GİDERİ | C2: 0 | D2: 2022 | E2: OCAK | F2: FERLA DIŞ TİC. LTD. | G2: İSTANBUL | H2: SAADET GÜLÜMSER YILDIRIM | I2: OY **** 2015 / ŞAHSİ | J2: 34 TR 4367 - BMV - ONUR | K2: FERLA | L2: 1-10 GÜN | M2: 36916680920 | N2: 29 EKİM İŞK.SAL. - İSMAİL KARAKUYU
A3: 2 | B3: ARAÇ OTOPARK VE VALE GİDERLERİ | C3: 1 | D3: 2023 | E3: ŞUBAT | F3: MESKUR KURUMSAL A.Ş. | G3: KÜTAHYA | H3: MESUT YILDIRIM | I3: OY **** 3328 / ŞAHSİ | J3: 34 TN 3948 - OPEL - CÜNEYT | K3: MESKUR | L3: 11-20 GÜN | M3: 1615960958 | N3: ACAR RESTAURANT - HAYRİ ACAR
A4: 3 | B4: ARAÇ TAMİR VE BAKIM GİDERLERİ | C4: 8 | D4: 2024 | E4: MART | G4: İZMİR | H4: ONUR YILDIRIM | I4: OY **** 7018 / ŞAHSİ | J4: 34 TP 4077 - AUDİ - MESUT | L4: 21-31 GÜN | M4: 80050303 | N4: AFACAN GIDA MAD.SAN.VE TİC.LTD.ŞTİ.
A5: 4 | B5: MUTFAK YİYECEK VE İÇECEK GİDERLERİ | C5: 10 | D5: 2025 | E5: NİSAN | G5: ADANA | H5: ELİF YILDIRIM CENKER | I5: OY **** 5243 / ŞAHSİ | J5: 34 FLZ 265 - RENAULT - MESUT | M5: 91514223 | N5: AFYON KARAMEHMET ET LTD.ŞTİ.
A6: 5 | B6: MUTFAK SARF MALZEME GİDERLERİ | C6: 18 | D6: 2026 | E6: MAYIS | G6: ADIYAMAN | H6: ADEM BÜLENT ÇİFTÇİ | I6: OY **** 3550 / ŞAHSİ | J6: KİRALIK OTO | M6: 101379841 | N6: AHENK REST.İŞLET.TUR.VE TİC.LTD.ŞTİ.
A7: 6 | B7: YİYECEK-İÇECEK GİDERLERİ | C7: 20 | D7: 2027 | E7: HAZİRAN | G7: AFYON | H7: CÜNEYT GÜNGÖRDÜ | I7: OY **** 1585 / ŞAHSİ | J7: 34 *** **** | M7: 100934876 | N7: AHSEN LEZZET GIDA SAN.VE TİC.LTD.ŞTİ.( MADO )
A8: 7 | B8: TEMSİL İKRAM VE YEMEK GİDERLERİ | C8: 26 | D8: 2028 | E8: TEMMUZ | G8: AĞRI | H8: TÜLAY KOLAK | I8: OY **** 1038 / ŞAHSİ | M8: 111193112 | N8: AK BÜFE VE KAFE.İŞL.İNŞ.OTO.TİC.PAZ.LTD.ŞTİ.
A9: 8 | B9: OFİS MAKİNA TAM.BAK.VE SARF MALZ. GİD. | D9: 2029 | E9: AĞUSTOS | G9: AMASYA | H9: HÜSEYİN SALMANLI | I9: OY **** 0121 / ŞAHSİ | M9: 280449529 | N9: AKAKAR MAD.YAĞ.İNŞ.GID.İTH.İHR.SAN.VE TİC.LTD.ŞTİ.
A10: 9 | B10: OFİS TAMİR, BAKIM VE ONARIM GİDERİ | D10: 2030 | E10: EYLÜL | G10: ANTALYA | I10: OY **** 7018 / ŞAHSİ | M10: 32654092810 | N10: AKAT PASTA CAFE - AYDIN AYDOĞDU
A11: 10 | B11: PTT, KARGO, NAKLİYE VE HAMMALİYE GİD. | D11: 2031 | E11: EKİM | G11: ARTVİN | I11: OY **** 5805 / ŞAHSİ | M11: 200529023 | N11: AKDEMİR REST.PETR.GID.TUR.SAN.VE TİC.LTD.ŞTİ.
A12: 11 | B12: KIRTASİYE VE MATBAA GİDERLERİ | D12: 2032 | E12: KASIM | G12: AYDIN | I12: OY **** 2023 / ŞAHSİ | M12: 520052325 | N12: ALİ MUHİDDİN HACI BEKİR ŞEKERCİLİK TİC.A.Ş.
A13: 12 | B13: YURTİÇİ SEYAHAT VE KONAKLAMA GİD. | D13: 2033 | E13: ARALIK | G13: BALIKESİR | I13: SY **** 1018 / ŞAHSİ - | M13: 25894342142 | N13: ALİCAN ALAĞAŞ
A14: 13 | B14: YURTDIŞI SEYAHAT VE KONAKLAMA GİD. | D14: 2034 | G14: BİLECİK | I14: SY **** 7425 / ŞAHSİ - | M14: 550428982 | N14: ALMANA YİYECEK İÇECEK SAN.VE TİC.LTD.ŞTİ.
A15: 14 | B15: TEMİZLİK VE SARF MALZEME GİDERLERİ | D15: 2035 | G15: BİNGÖL | I15: MY **** 9318 / ŞAHSİ - YKB | M15: 590358764 | N15: ALTACAN PETROL TİC.LTD.ŞTİ.
A16: 15 | B16: MUHTELİF VE DIŞARDAN SAĞ.HİZ.GİD. | D16: 2036 | G16: BİTLİS | I16: MY **** 9317 / ŞAHSİ - GARANTİ | M16: 610057673 | N16: ALTIN-BAŞAK UN VE UNLU MAM.İML.SAN.TİC.PAZ.LTD.ŞTİ.
A17: 16 | B17: DİĞER VERGİ RESİM VE HARÇ GİDERLERİ | D17: 2037 | G17: BOLU | I17: MY **** 0794 / ŞAHSİ - YKB | M17: 630236290 | N17: ALTINKILIÇLAR KAHVE KAK.ÜR.TİC.VE SAN.A.Ş.( KAHVEDÜNYASI )
A18: 17 | B18: NOTER GİDERLERİ | D18: 2038 | G18: BURDUR | I18: MY **** 3515 / ŞAHSİ - FİNANS | M18: 671133848 | N18: ALTUN GIDA İHTİYAÇ TÜK.MAD.İNŞ.SAN.VE TİC.A.Ş.
A19: 18 | B19: SAĞLIK GİDERLERİ | D19: 2039 | G19: BURSA | I19: MY **** 3204 / ŞAHSİ - FİNANS | M19: 6130398713 | N19: ANADOLU REST.İŞL.LTD.ŞTİ.
A20: 19 | B20: 689 KANUNEN KABUL EDİLMEYEN GİD. | G20: ÇANAKKALE | I20: MY **** 2334 / ŞAHSİ | M20: 680852855 | N20: ANAS REST.İŞLET.SAN.TİC.LTD.ŞTİ.
A21: 20 | G21: ÇANKIRI | I21: MY **** 9017 / ŞAHSİ | M21: 4790756205 | N21: ANT GOURMET HAY.GIDA ŞAR.VE TİC.LTD.ŞTİ.
A22: 21 | G22: ÇORUM | I22: EY **** 7425 / ŞAHSİ - | M22: 720039666 | N22: ARAS KARGO YURT İÇİ YURT DIŞI TAŞ.A.Ş.
A23: 22 | G23: DENİZLİ | I23: CG **** 6018 / ŞAHSİ - | M23: 850055513 | N23: ARTAŞ İNŞAAT SAN.VE TİC.A.Ş.
A24: 23 | G24: DİYARBAKIR | I24: CG **** 7112 / ŞAHSİ - | M24: 861280333 | N24: ASAY LEZZET GIDA TİC.LTD.ŞTİ.
A25: 24 | G25: EDİRNE | I25: HS **** 8088 / ŞAHSİ - | M25: 860528120 | N25: ASKEROĞLU TUR.GID.SAN.VE TİC.LTD.ŞTİ.
A26: 25 | G26: ELAZIĞ | I26: ŞK 5116 0533 / FERLA - KUVEYT - BUSINESS - 20 ANA KART | M26: 21553993434 | N26: ASMALI MESCİT DÜRÜMCÜSÜ - BELGİN BOĞDAY
A27: 26 | G27: ERZİNCAN | I27: ŞK 5116 7015 / FERLA - KUVEYT - BUSINESS - 20 MESUT | M27: 18638485564 | N27: ATA ŞARKÜTERİ - MUSTAFA ATA
A28: 27 | G28: ERZURUM | I28: ŞK 5116 4211 / FERLA - KUVEYT - BUSINESS - MESUT | M28: 920800525 | N28: ATA TEKNİK TAH.İNŞ.LTD.ŞTİ.
A29: 28 | G29: ESKİŞEHİR | I29: ŞK 5116 9392 / FERLA - KUVEYT - BUSINESS - 10 ELİF | M29: 12880463608 | N29: ATAKENT KEBAB - İBRAHİM ERDOĞAN
A30: 29 | G30: GAZİANTEP | I30: ŞK 5116 4522 / FERLA - KUVEYT - BUSINESS - 10 SAADET | M30: 950312550 | N30: ATALAY NAK.PET.OTO SAN.VE TİC.A.Ş.
A31: 30 | G31: GİRESUN | I31: ŞK 5398 8119 / FERLA - KUVEYT - MILES - 30 ANA | M31: 51166401712 | N31: ATASOYLAR TİCARET - MUSTAFA ATASOY
A32: 31 | G32: GÜMÜŞHANE | I32: ŞK 5398 9374 / FERLA - KUVEYT - MILES - 30 ELİF | M32: 1101094128 | N32: AYDENİZ GIDA VE TİC.LTD.ŞTİ.
... A44: 43 | G44: KÜTAHYA | I44: NAKİT / PARA | M44: 4590030594 | N44: BAŞTAŞ OTOM.SAN.VE TİC.A.Ş.
A45: 44 | G45: MALATYA | M45: 1550013468 | N45: BAYMER TURİZM VE YATIRIM A.Ş.
A46: 45 | G46: MANİSA | M46: 1620044730 | N46: BELBİM ELEKTRONİK PARA VE ÖD.HİZ.A.Ş.
A47: 46 | G47: KAHRAMANMARAŞ | M47: 1630026222 | N47: BELTAŞ BEŞİKTAŞ BELEDİYESİ İŞL.SAN.VE TİC.A.Ş.
A48: 47 | G48: MARDİN | M48: 1630054757 | N48: BELTUR BÜYÜK İST.EĞT.TUR.VE SAĞ.YAT.İŞL.A.Ş.
A49: 48 | G49: MUĞLA | M49: 9970668775 | N49: BEMCASADO GIDA SAN.VE TİC.LTD.ŞTİ.
A50: 49 | G50: MUŞ | M50: 1640433218 | N50: BERCESTE GRUP İNŞ.TUR.İŞL.AKAR.BAY.SAN.TİC.A.Ş.
A51: 50 | G51: NEVŞEHİR | M51: 1650184212 | N51: BEREKET HALK GIDA SAN.TİC.LTD.ŞTİ.(BEREKET DÖNER)
...

Sheet 03.AY O.Y. () 2026
A1: MASRAF LİSTESİ
A2: BELGE DÜZENLEME TARİHİ | D2: =+TODAY() -> 46127 | E2: BELGEYE AİT BİLGİLER | H2: TOPLAM: | I2: =SUBTOTAL(9,H4:H52) -> 3701 | N2: 0 | P2: 1 | R2: 10 | T2: 20 | V2: GENEL TOPLAMLAR
A3: S.N. | B3: BEL. AL. FİRMA ADI / UNVANI V.N. | C3: BELGENİN ALINDIĞI FİRMA ADI / UNVANI | D3: MASRAF TÜRÜ | E3: FATURA FİŞ NO | F3: BELGE TARİHİ | G3: KDV ORANI ( % … ) | H3: FİŞ GENEL TOPLAMI | I3: ÖDEME TÜRÜ | J3: MASRAF MERKEZİ | K3: ARAÇ PLAKA NO | L3: KKEG | M3: NET MATRAH | N3: MATRAH | O3: KDV | P3: MATRAH | Q3: KDV | R3: MATRAH | S3: KDV | T3: MATRAH | U3: KDV | V3: MATRAH TOPLAMI | W3: KDV TOPLAMI
A4: 1 | B4: 5270388270 | C4: =+VLOOKUP(B4,'VERİ BANKASI'!M:N,2,0) -> KASIMPAŞA SPOR KULÜBÜ DER.İKT.İŞL. | D4: ARAÇ OTOPARK VE VALE GİDERLERİ | E4: 35 | F4: 46099 | G4: 20 | H4: 260 | I4: NAKİT / PARA | J4: MESKUR | L4: =IF(OR(D4="ARAÇ YAKIT GİDERİ",D4="ARAÇ OTOPARK VE VALE GİDERLERİ",D4="ARAÇ TAMİR VE BAKIM GİDERLERİ"),H4*30/100,0)+(IF(D4="689 KANUNEN KABUL EDİLMEYEN GİD.",H4*1,0)) -> 78 | M4: =+H4-L4 -> 182 | N4: =+IF(G4=$N$2,M4,0) -> 0 | O4: =+N4*0/100 -> 0 | P4: =+IF(G4=$P$2,M4/1.01,0) -> 0 | Q4: =+P4*0.01 -> 0 | R4: =+IF(G4=$R$2,M4/1.1,0) -> 0 | S4: =+R4*0.1 -> 0 | T4: =+IF(G4=$T$2,M4/1.2,0) -> 151.66667 | U4: =+T4*0.2 -> 30.333333 | V4: =+N4+P4+R4+T4 -> 151.66667 | W4: =+O4+Q4+S4+U4 -> 30.333333
A5: 2 | B5: 3020249812 | C5: =+VLOOKUP(B5,'VERİ BANKASI'!M:N,2,0) -> DOCO PETROL VE DANIŞMANLIK A.Ş. | D5: YİYECEK-İÇECEK GİDERLERİ | E5: 451 | F5: 46101 | G5: 1 | H5: 126 | I5: OY **** 3328 / ŞAHSİ | J5: MESKUR | L5: =IF(OR(D5="ARAÇ YAKIT GİDERİ",D5="ARAÇ OTOPARK VE VALE GİDERLERİ",D5="ARAÇ TAMİR VE BAKIM GİDERLERİ"),H5*30/100,0)+(IF(D5="689 KANUNEN KABUL EDİLMEYEN GİD.",H5*1,0)) -> 0 | M5: =+H5-L5 -> 126 | N5: =+IF(G5=$N$2,M5,0) -> 0 | O5: =+N5*0/100 -> 0 | P5: =+IF(G5=$P$2,M5/1.01,0) -> 124.75248 | Q5: =+P5*0.01 -> 1.2475248 | R5: =+IF(G5=$R$2,M5/1.1,0) -> 0 | S5: =+R5*0.1 -> 0 | T5: =+IF(G5=$T$2,M5/1.2,0) -> 0 | U5: =+T5*0.2 -> 0 | V5: =+N5+P5+R5+T5 -> 124.75248 | W5: =+O5+Q5+S5+U5 -> 1.2475248
A6: 3 | J6: MESKUR | L6: =IF(OR(D6="ARAÇ YAKIT GİDERİ",D6="ARAÇ OTOPARK VE VALE GİDERLERİ",D6="ARAÇ TAMİR VE BAKIM GİDERLERİ"),H6*30/100,0)+(IF(D6="689 KANUNEN KABUL EDİLMEYEN GİD.",H6*1,0)) -> 0 | M6: =+H6-L6 -> 0 | N6: =+IF(G6=$N$2,M6,0) -> 0 | O6: =+N6*0/100 -> 0 | P6: =+IF(G6=$P$2,M6/1.01,0) -> 0 | Q6: =+P6*0.01 -> 0 | R6: =+IF(G6=$R$2,M6/1.1,0) -> 0 | S6: =+R6*0.1 -> 0 | T6: =+IF(G6=$T$2,M6/1.2,0) -> 0 | U6: =+T6*0.2 -> 0 | V6: =+N6+P6+R6+T6 -> 0 | W6: =+O6+Q6+S6+U6 -> 0
A7: 4 | B7: 6370192467 | C7: =+VLOOKUP(B7,'VERİ BANKASI'!M:N,2,0) -> OKAY GİYİM İNŞ.GIDA SAN.TİC.LTD.ŞTİ. | D7: YİYECEK-İÇECEK GİDERLERİ | E7: 191 | F7: 46106 | G7: 10 | H7: 200 | I7: OY **** 1038 / ŞAHSİ | J7: MESKUR | L7: =IF(OR(D7="ARAÇ YAKIT GİDERİ",D7="ARAÇ OTOPARK VE VALE GİDERLERİ",D7="ARAÇ TAMİR VE BAKIM GİDERLERİ"),H7*30/100,0)+(IF(D7="689 KANUNEN KABUL EDİLMEYEN GİD.",H7*1,0)) -> 0 | M7: =+H7-L7 -> 200 | N7: =+IF(G7=$N$2,M7,0) -> 0 | O7: =+N7*0/100 -> 0 | P7: =+IF(G7=$P$2,M7/1.01,0) -> 0 | Q7: =+P7*0.01 -> 0 | R7: =+IF(G7=$R$2,M7/1.1,0) -> 181.81818 | S7: =+R7*0.1 -> 18.181818 | T7: =+IF(G7=$T$2,M7/1.2,0) -> 0 | U7: =+T7*0.2 -> 0 | V7: =+N7+P7+R7+T7 -> 181.81818 | W7: =+O7+Q7+S7+U7 -> 18.181818
A8: 6 | B8: 4940070745 | C8: =+VLOOKUP(B8,'VERİ BANKASI'!M:N,2,0) -> KEREM PETROL ÜRÜNLERİ A.Ş. | D8: YİYECEK-İÇECEK GİDERLERİ | E8: 229 | F8: 46108 | G8: 1 | H8: 180 | I8: OY **** 1038 / ŞAHSİ | J8: MESKUR | L8: =IF(OR(D8="ARAÇ YAKIT GİDERİ",D8="ARAÇ OTOPARK VE VALE GİDERLERİ",D8="ARAÇ TAMİR VE BAKIM GİDERLERİ"),H8*30/100,0)+(IF(D8="689 KANUNEN KABUL EDİLMEYEN GİD.",H8*1,0)) -> 0 | M8: =+H8-L8 -> 180 | N8: =+IF(G8=$N$2,M8,0) -> 0 | O8: =+N8*0/100 -> 0 | P8: =+IF(G8=$P$2,M8/1.01,0) -> 178.21782 | Q8: =+P8*0.01 -> 1.7821782 | R8: =+IF(G8=$R$2,M8/1.1,0) -> 0 | S8: =+R8*0.1 -> 0 | T8: =+IF(G8=$T$2,M8/1.2,0) -> 0 | U8: =+T8*0.2 -> 0 | V8: =+N8+P8+R8+T8 -> 178.21782 | W8: =+O8+Q8+S8+U8 -> 1.7821782
A9: 7 | B9: 6131687717 | C9: =+VLOOKUP(B9,'VERİ BANKASI'!M:N,2,0) -> MAVİYILDIZ MUHALLEBİCİSİ A.Ş. | D9: YİYECEK-İÇECEK GİDERLERİ | E9: 7 | F9: 46112 | G9: 10 | H9: 1525 | I9: OY **** 5805 / ŞAHSİ | J9: MESKUR | L9: =IF(OR(D9="ARAÇ YAKIT GİDERİ",D9="ARAÇ OTOPARK VE VALE GİDERLERİ",D9="ARAÇ TAMİR VE BAKIM GİDERLERİ"),H9*30/100,0)+(IF(D9="689 KANUNEN KABUL EDİLMEYEN GİD.",H9*1,0)) -> 0 | M9: =+H9-L9 -> 1525 | N9: =+IF(G9=$N$2,M9,0) -> 0 | O9: =+N9*0/100 -> 0 | P9: =+IF(G9=$P$2,M9/1.01,0) -> 0 | Q9: =+P9*0.01 -> 0 | R9: =+IF(G9=$R$2,M9/1.1,0) -> 1386.3636 | S9: =+R9*0.1 -> 138.63636 | T9: =+IF(G9=$T$2,M9/1.2,0) -> 0 | U9: =+T9*0.2 -> 0 | V9: =+N9+P9+R9+T9 -> 1386.3636 | W9: =+O9+Q9+S9+U9 -> 138.63636
A10: 8 | B10: 5630636664 | C10: =+VLOOKUP(B10,'VERİ BANKASI'!M:N,2,0) -> KİLİSLİ ÖMER USTA GIDA LTD. ŞTİ. | D10: YİYECEK-İÇECEK GİDERLERİ | E10: 17 | F10: 46113 | G10: 10 | H10: 1410 | I10: OY **** 2023 / ŞAHSİ | J10: MESKUR | L10: =IF(OR(D10="ARAÇ YAKIT GİDERİ",D10="ARAÇ OTOPARK VE VALE GİDERLERİ",D10="ARAÇ TAMİR VE BAKIM GİDERLERİ"),H10*30/100,0)+(IF(D10="689 KANUNEN KABUL EDİLMEYEN GİD.",H10*1,0)) -> 0 | M10: =+H10-L10 -> 1410 | N10: =+IF(G10=$N$2,M10,0) -> 0 | O10: =+N10*0/100 -> 0 | P10: =+IF(G10=$P$2,M10/1.01,0) -> 0 | Q10: =+P10*0.01 -> 0 | R10: =+IF(G10=$R$2,M10/1.1,0) -> 1281.8182 | S10: =+R10*0.1 -> 128.18182 | T10: =+IF(G10=$T$2,M10/1.2,0) -> 0 | U10: =+T10*0.2 -> 0 | V10: =+N10+P10+R10+T10 -> 1281.8182 | W10: =+O10+Q10+S10+U10 -> 128.18182
A11: 9 | J11: MESKUR | L11: =IF(OR(D11="ARAÇ YAKIT GİDERİ",D11="ARAÇ OTOPARK VE VALE GİDERLERİ",D11="ARAÇ TAMİR VE BAKIM GİDERLERİ"),H11*30/100,0)+(IF(D11="689 KANUNEN KABUL EDİLMEYEN GİD.",H11*1,0)) -> 0 | M11: =+H11-L11 -> 0 | N11: =+IF(G11=$N$2,M11,0) -> 0 | O11: =+N11*0/100 -> 0 | P11: =+IF(G11=$P$2,M11/1.01,0) -> 0 | Q11: =+P11*0.01 -> 0 | R11: =+IF(G11=$R$2,M11/1.1,0) -> 0 | S11: =+R11*0.1 -> 0 | T11: =+IF(G11=$T$2,M11/1.2,0) -> 0 | U11: =+T11*0.2 -> 0 | V11: =+N11+P11+R11+T11 -> 0 | W11: =+O11+Q11+S11+U11 -> 0
A12: 12 | C12: =+VLOOKUP(B12,'VERİ BANKASI'!M:N,2,0) -> #N/A | J12: MESKUR | L12: =IF(OR(D12="ARAÇ YAKIT GİDERİ",D12="ARAÇ OTOPARK VE VALE GİDERLERİ",D12="ARAÇ TAMİR VE BAKIM GİDERLERİ"),H12*30/100,0)+(IF(D12="689 KANUNEN KABUL EDİLMEYEN GİD.",H12*1,0)) -> 0 | M12: =+H12-L12 -> 0 | N12: =+IF(G12=$N$2,M12,0) -> 0 | O12: =+N12*0/100 -> 0 | P12: =+IF(G12=$P$2,M12/1.01,0) -> 0 | Q12: =+P12*0.01 -> 0 | R12: =+IF(G12=$R$2,M12/1.1,0) -> 0 | S12: =+R12*0.1 -> 0 | T12: =+IF(G12=$T$2,M12/1.2,0) -> 0 | U12: =+T12*0.2 -> 0 | V12: =+N12+P12+R12+T12 -> 0 | W12: =+O12+Q12+S12+U12 -> 0
A13: 14 | C13: =+VLOOKUP(B13,'VERİ BANKASI'!M:N,2,0) -> #N/A | J13: MESKUR | L13: =IF(OR(D13="ARAÇ YAKIT GİDERİ",D13="ARAÇ OTOPARK VE VALE GİDERLERİ",D13="ARAÇ TAMİR VE BAKIM GİDERLERİ"),H13*30/100,0)+(IF(D13="689 KANUNEN KABUL EDİLMEYEN GİD.",H13*1,0)) -> 0 | M13: =+H13-L13 -> 0 | N13: =+IF(G13=$N$2,M13,0) -> 0 | O13: =+N13*0/100 -> 0 | P13: =+IF(G13=$P$2,M13/1.01,0) -> 0 | Q13: =+P13*0.01 -> 0 | R13: =+IF(G13=$R$2,M13/1.1,0) -> 0 | S13: =+R13*0.1 -> 0 | T13: =+IF(G13=$T$2,M13/1.2,0) -> 0 | U13: =+T13*0.2 -> 0 | V13: =+N13+P13+R13+T13 -> 0 | W13: =+O13+Q13+S13+U13 -> 0
A14: 15 | C14: =+VLOOKUP(B14,'VERİ BANKASI'!M:N,2,0) -> #N/A | J14: MESKUR | L14: =IF(OR(D14="ARAÇ YAKIT GİDERİ",D14="ARAÇ OTOPARK VE VALE GİDERLERİ",D14="ARAÇ TAMİR VE BAKIM GİDERLERİ"),H14*30/100,0)+(IF(D14="689 KANUNEN KABUL EDİLMEYEN GİD.",H14*1,0)) -> 0 | M14: =+H14-L14 -> 0 | N14: =+IF(G14=$N$2,M14,0) -> 0 | O14: =+N14*0/100 -> 0 | P14: =+IF(G14=$P$2,M14/1.01,0) -> 0 | Q14: =+P14*0.01 -> 0 | R14: =+IF(G14=$R$2,M14/1.1,0) -> 0 | S14: =+R14*0.1 -> 0 | T14: =+IF(G14=$T$2,M14/1.2,0) -> 0 | U14: =+T14*0.2 -> 0 | V14: =+N14+P14+R14+T14 -> 0 | W14: =+O14+Q14+S14+U14 -> 0
A15: 16 | C15: =+VLOOKUP(B15,'VERİ BANKASI'!M:N,2,0) -> #N/A | J15: MESKUR | L15: =IF(OR(D15="ARAÇ YAKIT GİDERİ",D15="ARAÇ OTOPARK VE VALE GİDERLERİ",D15="ARAÇ TAMİR VE BAKIM GİDERLERİ"),H15*30/100,0)+(IF(D15="689 KANUNEN KABUL EDİLMEYEN GİD.",H15*1,0)) -> 0 | M15: =+H15-L15 -> 0 | N15: =+IF(G15=$N$2,M15,0) -> 0 | O15: =+N15*0/100 -> 0 | P15: =+IF(G15=$P$2,M15/1.01,0) -> 0 | Q15: =+P15*0.01 -> 0 | R15: =+IF(G15=$R$2,M15/1.1,0) -> 0 | S15: =+R15*0.1 -> 0 | T15: =+IF(G15=$T$2,M15/1.2,0) -> 0 | U15: =+T15*0.2 -> 0 | V15: =+N15+P15+R15+T15 -> 0 | W15: =+O15+Q15+S15+U15 -> 0
A16: 17 | C16: =+VLOOKUP(B16,'VERİ BANKASI'!M:N,2,0) -> #N/A | J16: MESKUR | L16: =IF(OR(D16="ARAÇ YAKIT GİDERİ",D16="ARAÇ OTOPARK VE VALE GİDERLERİ",D16="ARAÇ TAMİR VE BAKIM GİDERLERİ"),H16*30/100,0)+(IF(D16="689 KANUNEN KABUL EDİLMEYEN GİD.",H16*1,0)) -> 0 | M16: =+H16-L16 -> 0 | N16: =+IF(G16=$N$2,M16,0) -> 0 | O16: =+N16*0/100 -> 0 | P16: =+IF(G16=$P$2,M16/1.01,0) -> 0 | Q16: =+P16*0.01 -> 0 | R16: =+IF(G16=$R$2,M16/1.1,0) -> 0 | S16: =+R16*0.1 -> 0 | T16: =+IF(G16=$T$2,M16/1.2,0) -> 0 | U16: =+T16*0.2 -> 0 | V16: =+N16+P16+R16+T16 -> 0 | W16: =+O16+Q16+S16+U16 -> 0
A17: 18 | C17: =+VLOOKUP(B17,'VERİ BANKASI'!M:N,2,0) -> #N/A | J17: MESKUR | L17: =IF(OR(D17="ARAÇ YAKIT GİDERİ",D17="ARAÇ OTOPARK VE VALE GİDERLERİ",D17="ARAÇ TAMİR VE BAKIM GİDERLERİ"),H17*30/100,0)+(IF(D17="689 KANUNEN KABUL EDİLMEYEN GİD.",H17*1,0)) -> 0 | M17: =+H17-L17 -> 0 | N17: =+IF(G17=$N$2,M17,0) -> 0 | O17: =+N17*0/100 -> 0 | P17: =+IF(G17=$P$2,M17/1.01,0) -> 0 | Q17: =+P17*0.01 -> 0 | R17: =+IF(G17=$R$2,M17/1.1,0) -> 0 | S17: =+R17*0.1 -> 0 | T17: =+IF(G17=$T$2,M17/1.2,0) -> 0 | U17: =+T17*0.2 -> 0 | V17: =+N17+P17+R17+T17 -> 0 | W17: =+O17+Q17+S17+U17 -> 0
A18: 19 | C18: =+VLOOKUP(B18,'VERİ BANKASI'!M:N,2,0) -> #N/A | J18: MESKUR | L18: =IF(OR(D18="ARAÇ YAKIT GİDERİ",D18="ARAÇ OTOPARK VE VALE GİDERLERİ",D18="ARAÇ TAMİR VE BAKIM GİDERLERİ"),H18*30/100,0)+(IF(D18="689 KANUNEN KABUL EDİLMEYEN GİD.",H18*1,0)) -> 0 | M18: =+H18-L18 -> 0 | N18: =+IF(G18=$N$2,M18,0) -> 0 | O18: =+N18*0/100 -> 0 | P18: =+IF(G18=$P$2,M18/1.01,0) -> 0 | Q18: =+P18*0.01 -> 0 | R18: =+IF(G18=$R$2,M18/1.1,0) -> 0 | S18: =+R18*0.1 -> 0 | T18: =+IF(G18=$T$2,M18/1.2,0) -> 0 | U18: =+T18*0.2 -> 0 | V18: =+N18+P18+R18+T18 -> 0 | W18: =+O18+Q18+S18+U18 -> 0
A19: 20 | C19: =+VLOOKUP(B19,'VERİ BANKASI'!M:N,2,0) -> #N/A | J19: MESKUR | L19: =IF(OR(D19="ARAÇ YAKIT GİDERİ",D19="ARAÇ OTOPARK VE VALE GİDERLERİ",D19="ARAÇ TAMİR VE BAKIM GİDERLERİ"),H19*30/100,0)+(IF(D19="689 KANUNEN KABUL EDİLMEYEN GİD.",H19*1,0)) -> 0 | M19: =+H19-L19 -> 0 | N19: =+IF(G19=$N$2,M19,0) -> 0 | O19: =+N19*0/100 -> 0 | P19: =+IF(G19=$P$2,M19/1.01,0) -> 0 | Q19: =+P19*0.01 -> 0 | R19: =+IF(G19=$R$2,M19/1.1,0) -> 0 | S19: =+R19*0.1 -> 0 | T19: =+IF(G19=$T$2,M19/1.2,0) -> 0 | U19: =+T19*0.2 -> 0 | V19: =+N19+P19+R19+T19 -> 0 | W19: =+O19+Q19+S19+U19 -> 0
A20: 21 | C20: =+VLOOKUP(B20,'VERİ BANKASI'!M:N,2,0) -> #N/A | J20: MESKUR | L20: =IF(OR(D20="ARAÇ YAKIT GİDERİ",D20="ARAÇ OTOPARK VE VALE GİDERLERİ",D20="ARAÇ TAMİR VE BAKIM GİDERLERİ"),H20*30/100,0)+(IF(D20="689 KANUNEN KABUL EDİLMEYEN GİD.",H20*1,0)) -> 0 | M20: =+H20-L20 -> 0 | N20: =+IF(G20=$N$2,M20,0) -> 0 | O20: =+N20*0/100 -> 0 | P20: =+IF(G20=$P$2,M20/1.01,0) -> 0 | Q20: =+P20*0.01 -> 0 | R20: =+IF(G20=$R$2,M20/1.1,0) -> 0 | S20: =+R20*0.1 -> 0 | T20: =+IF(G20=$T$2,M20/1.2,0) -> 0 | U20: =+T20*0.2 -> 0 | V20: =+N20+P20+R20+T20 -> 0 | W20: =+O20+Q20+S20+U20 -> 0
A21: 22 | C21: =+VLOOKUP(B21,'VERİ BANKASI'!M:N,2,0) -> #N/A | J21: MESKUR | L21: =IF(OR(D21="ARAÇ YAKIT GİDERİ",D21="ARAÇ OTOPARK VE VALE GİDERLERİ",D21="ARAÇ TAMİR VE BAKIM GİDERLERİ"),H21*30/100,0)+(IF(D21="689 KANUNEN KABUL EDİLMEYEN GİD.",H21*1,0)) -> 0 | M21: =+H21-L21 -> 0 | N21: =+IF(G21=$N$2,M21,0) -> 0 | O21: =+N21*0/100 -> 0 | P21: =+IF(G21=$P$2,M21/1.01,0) -> 0 | Q21: =+P21*0.01 -> 0 | R21: =+IF(G21=$R$2,M21/1.1,0) -> 0 | S21: =+R21*0.1 -> 0 | T21: =+IF(G21=$T$2,M21/1.2,0) -> 0 | U21: =+T21*0.2 -> 0 | V21: =+N21+P21+R21+T21 -> 0 | W21: =+O21+Q21+S21+U21 -> 0
A22: 23 | C22: =+VLOOKUP(B22,'VERİ BANKASI'!M:N,2,0) -> #N/A | J22: MESKUR | L22: =IF(OR(D22="ARAÇ YAKIT GİDERİ",D22="ARAÇ OTOPARK VE VALE GİDERLERİ",D22="ARAÇ TAMİR VE BAKIM GİDERLERİ"),H22*30/100,0)+(IF(D22="689 KANUNEN KABUL EDİLMEYEN GİD.",H22*1,0)) -> 0 | M22: =+H22-L22 -> 0 | N22: =+IF(G22=$N$2,M22,0) -> 0 | O22: =+N22*0/100 -> 0 | P22: =+IF(G22=$P$2,M22/1.01,0) -> 0 | Q22: =+P22*0.01 -> 0 | R22: =+IF(G22=$R$2,M22/1.1,0) -> 0 | S22: =+R22*0.1 -> 0 | T22: =+IF(G22=$T$2,M22/1.2,0) -> 0 | U22: =+T22*0.2 -> 0 | V22: =+N22+P22+R22+T22 -> 0 | W22: =+O22+Q22+S22+U22 -> 0
A23: 24 | C23: =+VLOOKUP(B23,'VERİ BANKASI'!M:N,2,0) -> #N/A | J23: MESKUR | L23: =IF(OR(D23="ARAÇ YAKIT GİDERİ",D23="ARAÇ OTOPARK VE VALE GİDERLERİ",D23="ARAÇ TAMİR VE BAKIM GİDERLERİ"),H23*30/100,0)+(IF(D23="689 KANUNEN KABUL EDİLMEYEN GİD.",H23*1,0)) -> 0 | M23: =+H23-L23 -> 0 | N23: =+IF(G23=$N$2,M23,0) -> 0 | O23: =+N23*0/100 -> 0 | P23: =+IF(G23=$P$2,M23/1.01,0) -> 0 | Q23: =+P23*0.01 -> 0 | R23: =+IF(G23=$R$2,M23/1.1,0) -> 0 | S23: =+R23*0.1 -> 0 | T23: =+IF(G23=$T$2,M23/1.2,0) -> 0 | U23: =+T23*0.2 -> 0 | V23: =+N23+P23+R23+T23 -> 0 | W23: =+O23+Q23+S23+U23 -> 0
... A50: 51 | C50: =+VLOOKUP(B50,'VERİ BANKASI'!M:N,2,0) -> #N/A | J50: MESKUR | L50: =IF(OR(D50="ARAÇ YAKIT GİDERİ",D50="ARAÇ OTOPARK VE VALE GİDERLERİ",D50="ARAÇ TAMİR VE BAKIM GİDERLERİ"),H50*30/100,0)+(IF(D50="689 KANUNEN KABUL EDİLMEYEN GİD.",H50*1,0)) -> 0 | M50: =+H50-L50 -> 0 | N50: =+IF(G50=$N$2,M50,0) -> 0 | O50: =+N50*0/100 -> 0 | P50: =+IF(G50=$P$2,M50/1.01,0) -> 0 | Q50: =+P50*0.01 -> 0 | R50: =+IF(G50=$R$2,M50/1.1,0) -> 0 | S50: =+R50*0.1 -> 0 | T50: =+IF(G50=$T$2,M50/1.2,0) -> 0 | U50: =+T50*0.2 -> 0 | V50: =+N50+P50+R50+T50 -> 0 | W50: =+O50+Q50+S50+U50 -> 0
C53: TOPLAMLAR | H53: =SUBTOTAL(9,H4:H52) -> 3701 | L53: =+SUBTOTAL(9,L4:L51) -> 78 | M53: =+SUBTOTAL(9,M4:M51) -> 3623 | N53: =+SUBTOTAL(9,N4:N51) -> 0 | O53: =+SUBTOTAL(9,O4:O51) -> 0 | P53: =+SUBTOTAL(9,P4:P51) -> 302.9703 | Q53: =+SUBTOTAL(9,Q4:Q51) -> 3.029703 | R53: =+SUBTOTAL(9,R4:R51) -> 2850 | S53: =+SUBTOTAL(9,S4:S51) -> 285 | ... W53: =+SUBTOTAL(9,W4:W51) -> 318.36304
A55: S.N. | B55: MASRAF DAĞILIMI | C55: MATRAH %0 | D55: KDV %0 | E55: MATRAH %1 | F55: KDV %1 | G55: MATRAH %10 | H55: KDV %10 | I55: MATRAH%20 | J55: KDV%20 | K55: KKEG | L55: Toplam | M55: BELGE ADETİ | O55: PER. ADI | P55: ONUR YILDIRIM | T55: ALINAN AVANS TOPLAMI | W55: 0
A56: 1 | B56: =+'VERİ BANKASI'!B2 -> ARAÇ YAKIT GİDERİ | C56: =SUMIF($D$4:$D$51,B56,$N$4:$N$51) -> 0 | D56: =SUMIF($D$4:$D$51,B56,$O$4:$O$51) -> 0 | E56: =SUMIF($D$4:$D$51,B56,$P$4:$P$51) -> 0 | F56: =SUMIF($D$4:$D$51,B56,$Q$4:$Q$51) -> 0 | G56: =SUMIF($D$4:$D$51,B56,$R$4:$R$51) -> 0 | H56: =SUMIF($D$4:$D$51,B56,$S$4:$S$51) -> 0 | I56: =SUMIF($D$4:$D$51,B56,$T$4:$T$51) -> 0 | J56: =SUMIF($D$4:$D$51,B56,$U$4:$U$51) -> 0 | K56: =SUMIF($D$4:$D$51,B56,$L$4:$L$51) -> 0 | L56: =+SUM(C56:K56) -> 0 | M56: =+COUNTIF($D$4:D49,B56) -> 0 | O56: ŞİRKET | P56: MESKUR KURUMSAL A.Ş.
A57: 2 | B57: =+'VERİ BANKASI'!B3 -> ARAÇ OTOPARK VE VALE GİDERLERİ | C57: =SUMIF($D$4:$D$51,B57,$N$4:$N$51) -> 0 | D57: =SUMIF($D$4:$D$51,B57,$O$4:$O$51) -> 0 | E57: =SUMIF($D$4:$D$51,B57,$P$4:$P$51) -> 0 | F57: =SUMIF($D$4:$D$51,B57,$Q$4:$Q$51) -> 0 | G57: =SUMIF($D$4:$D$51,B57,$R$4:$R$51) -> 0 | H57: =SUMIF($D$4:$D$51,B57,$S$4:$S$51) -> 0 | I57: =SUMIF($D$4:$D$51,B57,$T$4:$T$51) -> 151.66667 | J57: =SUMIF($D$4:$D$51,B57,$U$4:$U$51) -> 30.333333 | K57: =SUMIF($D$4:$D$51,B57,$L$4:$L$51) -> 78 | L57: =+SUM(C57:K57) -> 260 | M57: =+COUNTIF($D$4:D51,B57) -> 1 | O57: İŞYERİ | P57: İSTANBUL | T57: HARCAMA TOPLAMA | W57: =+L53+V53+W53 -> 3701
A58: 3 | B58: =+'VERİ BANKASI'!B4 -> ARAÇ TAMİR VE BAKIM GİDERLERİ | C58: =SUMIF($D$4:$D$51,B58,$N$4:$N$51) -> 0 | D58: =SUMIF($D$4:$D$51,B58,$O$4:$O$51) -> 0 | E58: =SUMIF($D$4:$D$51,B58,$P$4:$P$51) -> 0 | F58: =SUMIF($D$4:$D$51,B58,$Q$4:$Q$51) -> 0 | G58: =SUMIF($D$4:$D$51,B58,$R$4:$R$51) -> 0 | H58: =SUMIF($D$4:$D$51,B58,$S$4:$S$51) -> 0 | I58: =SUMIF($D$4:$D$51,B58,$T$4:$T$51) -> 0 | J58: =SUMIF($D$4:$D$51,B58,$U$4:$U$51) -> 0 | K58: =SUMIF($D$4:$D$51,B58,$L$4:$L$51) -> 0 | L58: =+SUM(C58:K58) -> 0 | M58: =+COUNTIF($D$4:D52,B58) -> 0 | O58: YIL | P58: 2025
A59: 4 | B59: =+'VERİ BANKASI'!B5 -> MUTFAK YİYECEK VE İÇECEK GİDERLERİ | C59: =SUMIF($D$4:$D$51,B59,$N$4:$N$51) -> 0 | D59: =SUMIF($D$4:$D$51,B59,$O$4:$O$51) -> 0 | E59: =SUMIF($D$4:$D$51,B59,$P$4:$P$51) -> 0 | F59: =SUMIF($D$4:$D$51,B59,$Q$4:$Q$51) -> 0 | G59: =SUMIF($D$4:$D$51,B59,$R$4:$R$51) -> 0 | H59: =SUMIF($D$4:$D$51,B59,$S$4:$S$51) -> 0 | I59: =SUMIF($D$4:$D$51,B59,$T$4:$T$51) -> 0 | J59: =SUMIF($D$4:$D$51,B59,$U$4:$U$51) -> 0 | K59: =SUMIF($D$4:$D$51,B59,$L$4:$L$51) -> 0 | L59: =+SUM(C59:K59) -> 0 | M59: =+COUNTIF($D$4:D53,B59) -> 0 | O59: AY | P59: EKİM | T59: FARK | W59: =+W55-W57 -> -3701
A60: 5 | B60: =+'VERİ BANKASI'!B6 -> MUTFAK SARF MALZEME GİDERLERİ | C60: =SUMIF($D$4:$D$51,B60,$N$4:$N$51) -> 0 | D60: =SUMIF($D$4:$D$51,B60,$O$4:$O$51) -> 0 | E60: =SUMIF($D$4:$D$51,B60,$P$4:$P$51) -> 0 | F60: =SUMIF($D$4:$D$51,B60,$Q$4:$Q$51) -> 0 | G60: =SUMIF($D$4:$D$51,B60,$R$4:$R$51) -> 0 | H60: =SUMIF($D$4:$D$51,B60,$S$4:$S$51) -> 0 | I60: =SUMIF($D$4:$D$51,B60,$T$4:$T$51) -> 0 | J60: =SUMIF($D$4:$D$51,B60,$U$4:$U$51) -> 0 | K60: =SUMIF($D$4:$D$51,B60,$L$4:$L$51) -> 0 | L60: =+SUM(C60:K60) -> 0 | M60: =+COUNTIF($D$4:D54,B60) -> 0 | O60: GÜN | P60: 1-10 GÜN
A61: 6 | B61: =+'VERİ BANKASI'!B7 -> YİYECEK-İÇECEK GİDERLERİ | C61: =SUMIF($D$4:$D$51,B61,$N$4:$N$51) -> 0 | D61: =SUMIF($D$4:$D$51,B61,$O$4:$O$51) -> 0 | E61: =SUMIF($D$4:$D$51,B61,$P$4:$P$51) -> 302.9703 | F61: =SUMIF($D$4:$D$51,B61,$Q$4:$Q$51) -> 3.029703 | G61: =SUMIF($D$4:$D$51,B61,$R$4:$R$51) -> 2850 | H61: =SUMIF($D$4:$D$51,B61,$S$4:$S$51) -> 285 | I61: =SUMIF($D$4:$D$51,B61,$T$4:$T$51) -> 0 | J61: =SUMIF($D$4:$D$51,B61,$U$4:$U$51) -> 0 | K61: =SUMIF($D$4:$D$51,B61,$L$4:$L$51) -> 0 | L61: =+SUM(C61:K61) -> 3441 | M61: =+COUNTIF($D$4:D55,B61) -> 5
A62: 7 | B62: =+'VERİ BANKASI'!B8 -> TEMSİL İKRAM VE YEMEK GİDERLERİ | C62: =SUMIF($D$4:$D$51,B62,$N$4:$N$51) -> 0 | D62: =SUMIF($D$4:$D$51,B62,$O$4:$O$51) -> 0 | E62: =SUMIF($D$4:$D$51,B62,$P$4:$P$51) -> 0 | F62: =SUMIF($D$4:$D$51,B62,$Q$4:$Q$51) -> 0 | G62: =SUMIF($D$4:$D$51,B62,$R$4:$R$51) -> 0 | H62: =SUMIF($D$4:$D$51,B62,$S$4:$S$51) -> 0 | I62: =SUMIF($D$4:$D$51,B62,$T$4:$T$51) -> 0 | J62: =SUMIF($D$4:$D$51,B62,$U$4:$U$51) -> 0 | K62: =SUMIF($D$4:$D$51,B62,$L$4:$L$51) -> 0 | L62: =+SUM(C62:K62) -> 0 | M62: =+COUNTIF($D$4:D55,B62) -> 0
A63: 8 | B63: =+'VERİ BANKASI'!B9 -> OFİS MAKİNA TAM.BAK.VE SARF MALZ. GİD. | C63: =SUMIF($D$4:$D$51,B63,$N$4:$N$51) -> 0 | D63: =SUMIF($D$4:$D$51,B63,$O$4:$O$51) -> 0 | E63: =SUMIF($D$4:$D$51,B63,$P$4:$P$51) -> 0 | F63: =SUMIF($D$4:$D$51,B63,$Q$4:$Q$51) -> 0 | G63: =SUMIF($D$4:$D$51,B63,$R$4:$R$51) -> 0 | H63: =SUMIF($D$4:$D$51,B63,$S$4:$S$51) -> 0 | I63: =SUMIF($D$4:$D$51,B63,$T$4:$T$51) -> 0 | J63: =SUMIF($D$4:$D$51,B63,$U$4:$U$51) -> 0 | K63: =SUMIF($D$4:$D$51,B63,$L$4:$L$51) -> 0 | L63: =+SUM(C63:K63) -> 0 | M63: =+COUNTIF($D$4:D56,B63) -> 0 | O63: PERSONEL | T63: ONAY MAKAMI
A64: 9 | B64: =+'VERİ BANKASI'!B10 -> OFİS TAMİR, BAKIM VE ONARIM GİDERİ | C64: =SUMIF($D$4:$D$51,B64,$N$4:$N$51) -> 0 | D64: =SUMIF($D$4:$D$51,B64,$O$4:$O$51) -> 0 | E64: =SUMIF($D$4:$D$51,B64,$P$4:$P$51) -> 0 | F64: =SUMIF($D$4:$D$51,B64,$Q$4:$Q$51) -> 0 | G64: =SUMIF($D$4:$D$51,B64,$R$4:$R$51) -> 0 | H64: =SUMIF($D$4:$D$51,B64,$S$4:$S$51) -> 0 | I64: =SUMIF($D$4:$D$51,B64,$T$4:$T$51) -> 0 | J64: =SUMIF($D$4:$D$51,B64,$U$4:$U$51) -> 0 | K64: =SUMIF($D$4:$D$51,B64,$L$4:$L$51) -> 0 | L64: =+SUM(C64:K64) -> 0 | M64: =+COUNTIF($D$4:D57,B64) -> 0
A65: 10 | B65: =+'VERİ BANKASI'!B11 -> PTT, KARGO, NAKLİYE VE HAMMALİYE GİD. | C65: =SUMIF($D$4:$D$51,B65,$N$4:$N$51) -> 0 | D65: =SUMIF($D$4:$D$51,B65,$O$4:$O$51) -> 0 | E65: =SUMIF($D$4:$D$51,B65,$P$4:$P$51) -> 0 | F65: =SUMIF($D$4:$D$51,B65,$Q$4:$Q$51) -> 0 | G65: =SUMIF($D$4:$D$51,B65,$R$4:$R$51) -> 0 | H65: =SUMIF($D$4:$D$51,B65,$S$4:$S$51) -> 0 | I65: =SUMIF($D$4:$D$51,B65,$T$4:$T$51) -> 0 | J65: =SUMIF($D$4:$D$51,B65,$U$4:$U$51) -> 0 | K65: =SUMIF($D$4:$D$51,B65,$L$4:$L$51) -> 0 | L65: =+SUM(C65:K65) -> 0 | M65: =+COUNTIF($D$4:D58,B65) -> 0 | O65: AD SOYAD | P65: =+CONCATENATE(P66,P55) -> : ONUR YILDIRIM | T65: AD SOYAD | U65: : SAADET GÜLÜMSER YILDIRIM
A66: 11 | B66: =+'VERİ BANKASI'!B12 -> KIRTASİYE VE MATBAA GİDERLERİ | C66: =SUMIF($D$4:$D$51,B66,$N$4:$N$51) -> 0 | D66: =SUMIF($D$4:$D$51,B66,$O$4:$O$51) -> 0 | E66: =SUMIF($D$4:$D$51,B66,$P$4:$P$51) -> 0 | F66: =SUMIF($D$4:$D$51,B66,$Q$4:$Q$51) -> 0 | G66: =SUMIF($D$4:$D$51,B66,$R$4:$R$51) -> 0 | H66: =SUMIF($D$4:$D$51,B66,$S$4:$S$51) -> 0 | I66: =SUMIF($D$4:$D$51,B66,$T$4:$T$51) -> 0 | J66: =SUMIF($D$4:$D$51,B66,$U$4:$U$51) -> 0 | K66: =SUMIF($D$4:$D$51,B66,$L$4:$L$51) -> 0 | L66: =+SUM(C66:K66) -> 0 | M66: =+COUNTIF($D$4:D59,B66) -> 0 | O66: İMZA | P66: : | T66: İMZA | U66: :
A67: 12 | B67: =+'VERİ BANKASI'!B13 -> YURTİÇİ SEYAHAT VE KONAKLAMA GİD. | C67: =SUMIF($D$4:$D$51,B67,$N$4:$N$51) -> 0 | D67: =SUMIF($D$4:$D$51,B67,$O$4:$O$51) -> 0 | E67: =SUMIF($D$4:$D$51,B67,$P$4:$P$51) -> 0 | F67: =SUMIF($D$4:$D$51,B67,$Q$4:$Q$51) -> 0 | G67: =SUMIF($D$4:$D$51,B67,$R$4:$R$51) -> 0 | H67: =SUMIF($D$4:$D$51,B67,$S$4:$S$51) -> 0 | I67: =SUMIF($D$4:$D$51,B67,$T$4:$T$51) -> 0 | J67: =SUMIF($D$4:$D$51,B67,$U$4:$U$51) -> 0 | K67: =SUMIF($D$4:$D$51,B67,$L$4:$L$51) -> 0 | L67: =+SUM(C67:K67) -> 0 | M67: =+COUNTIF($D$4:D60,B67) -> 0 | O67: TARİH : | T67: TARİH :
A68: 13 | B68: =+'VERİ BANKASI'!B14 -> YURTDIŞI SEYAHAT VE KONAKLAMA GİD. | C68: =SUMIF($D$4:$D$51,B68,$N$4:$N$51) -> 0 | D68: =SUMIF($D$4:$D$51,B68,$O$4:$O$51) -> 0 | E68: =SUMIF($D$4:$D$51,B68,$P$4:$P$51) -> 0 | F68: =SUMIF($D$4:$D$51,B68,$Q$4:$Q$51) -> 0 | G68: =SUMIF($D$4:$D$51,B68,$R$4:$R$51) -> 0 | H68: =SUMIF($D$4:$D$51,B68,$S$4:$S$51) -> 0 | I68: =SUMIF($D$4:$D$51,B68,$T$4:$T$51) -> 0 | J68: =SUMIF($D$4:$D$51,B68,$U$4:$U$51) -> 0 | K68: =SUMIF($D$4:$D$51,B68,$L$4:$L$51) -> 0 | L68: =+SUM(C68:K68) -> 0 | M68: =+COUNTIF($D$4:D62,B68) -> 0
A69: 14 | B69: =+'VERİ BANKASI'!B15 -> TEMİZLİK VE SARF MALZEME GİDERLERİ | C69: =SUMIF($D$4:$D$51,B69,$N$4:$N$51) -> 0 | D69: =SUMIF($D$4:$D$51,B69,$O$4:$O$51) -> 0 | E69: =SUMIF($D$4:$D$51,B69,$P$4:$P$51) -> 0 | F69: =SUMIF($D$4:$D$51,B69,$Q$4:$Q$51) -> 0 | G69: =SUMIF($D$4:$D$51,B69,$R$4:$R$51) -> 0 | H69: =SUMIF($D$4:$D$51,B69,$S$4:$S$51) -> 0 | I69: =SUMIF($D$4:$D$51,B69,$T$4:$T$51) -> 0 | J69: =SUMIF($D$4:$D$51,B69,$U$4:$U$51) -> 0 | K69: =SUMIF($D$4:$D$51,B69,$L$4:$L$51) -> 0 | L69: =+SUM(C69:K69) -> 0 | M69: =+COUNTIF($D$4:D63,B69) -> 0
...

Sheet 01.AY O.Y. (11-20 ARASI) 2026
A1: MASRAF LİSTESİ
A2: BELGE DÜZENLEME TARİHİ | D2: =+TODAY() -> 46127 | E2: BELGEYE AİT BİLGİLER | H2: TOPLAM: | I2: =SUBTOTAL(9,H4:H52) -> 6159.39 | N2: 0 | P2: 1 | R2: 10 | T2: 20 | V2: GENEL TOPLAMLAR
A3: S.N. | B3: BEL. AL. FİRMA ADI / UNVANI V.N. | C3: BELGENİN ALINDIĞI FİRMA ADI / UNVANI | D3: MASRAF TÜRÜ | E3: FATURA FİŞ NO | F3: BELGE TARİHİ | G3: KDV ORANI ( % … ) | H3: FİŞ GENEL TOPLAMI | I3: ÖDEME TÜRÜ | J3: MASRAF MERKEZİ | K3: ARAÇ PLAKA NO | L3: KKEG | M3: NET MATRAH | N3: MATRAH | O3: KDV | P3: MATRAH | Q3: KDV | R3: MATRAH | S3: KDV | T3: MATRAH | U3: KDV | V3: MATRAH TOPLAMI | W3: KDV TOPLAMI
A4: 1 | B4: 2911768928 | C4: =+VLOOKUP(B4,'VERİ BANKASI'!M:N,2,0) -> DENİZ POLAT TUR.VE EĞ.HİZ.TİC.LTD.ŞTİ. | D4: YİYECEK-İÇECEK GİDERLERİ | E4: 4 | F4: 46037 | G4: 10 | H4: 2850 | I4: OY **** 5805 / ŞAHSİ | J4: MESKUR | L4: =IF(OR(D4="ARAÇ YAKIT GİDERİ",D4="ARAÇ OTOPARK VE VALE GİDERLERİ",D4="ARAÇ TAMİR VE BAKIM GİDERLERİ"),H4*30/100,0)+(IF(D4="689 KANUNEN KABUL EDİLMEYEN GİD.",H4*1,0)) -> 0 | M4: =+H4-L4 -> 2850 | N4: =+IF(G4=$N$2,M4,0) -> 0 | O4: =+N4*0/100 -> 0 | P4: =+IF(G4=$P$2,M4/1.01,0) -> 0 | Q4: =+P4*0.01 -> 0 | R4: =+IF(G4=$R$2,M4/1.1,0) -> 2590.9091 | S4: =+R4*0.1 -> 259.09091 | T4: =+IF(G4=$T$2,M4/1.2,0) -> 0 | U4: =+T4*0.2 -> 0 | V4: =+N4+P4+R4+T4 -> 2590.9091 | W4: =+O4+Q4+S4+U4 -> 259.09091
A5: 2 | B5: 8400052427 | C5: =+VLOOKUP(B5,'VERİ BANKASI'!M:N,2,0) -> TEŞVİKİYE SARAY GIDA A.Ş.(SARAY MUHALLEBİCİSİ) | D5: YİYECEK-İÇECEK GİDERLERİ | E5: 23 | F5: 46036 | G5: 10 | H5: 825 | I5: OY **** 5805 / ŞAHSİ | J5: MESKUR | L5: =IF(OR(D5="ARAÇ YAKIT GİDERİ",D5="ARAÇ OTOPARK VE VALE GİDERLERİ",D5="ARAÇ TAMİR VE BAKIM GİDERLERİ"),H5*30/100,0)+(IF(D5="689 KANUNEN KABUL EDİLMEYEN GİD.",H5*1,0)) -> 0 | M5: =+H5-L5 -> 825 | N5: =+IF(G5=$N$2,M5,0) -> 0 | O5: =+N5*0/100 -> 0 | P5: =+IF(G5=$P$2,M5/1.01,0) -> 0 | Q5: =+P5*0.01 -> 0 | R5: =+IF(G5=$R$2,M5/1.1,0) -> 750 | S5: =+R5*0.1 -> 75 | T5: =+IF(G5=$T$2,M5/1.2,0) -> 0 | U5: =+T5*0.2 -> 0 | V5: =+N5+P5+R5+T5 -> 750 | W5: =+O5+Q5+S5+U5 -> 75
A6: 3 | C6: =+VLOOKUP(B6,'VERİ BANKASI'!M:N,2,0) -> #N/A | D6: YURTİÇİ SEYAHAT VE KONAKLAMA GİD. | E6: 1422 | F6: 46036 | H6: 563.88 | I6: OY **** 5805 / ŞAHSİ | J6: MESKUR | L6: =IF(OR(D6="ARAÇ YAKIT GİDERİ",D6="ARAÇ OTOPARK VE VALE GİDERLERİ",D6="ARAÇ TAMİR VE BAKIM GİDERLERİ"),H6*30/100,0)+(IF(D6="689 KANUNEN KABUL EDİLMEYEN GİD.",H6*1,0)) -> 0 | M6: =+H6-L6 -> 563.88 | N6: =+IF(G6=$N$2,M6,0) -> 563.88 | O6: =+N6*0/100 -> 0 | P6: =+IF(G6=$P$2,M6/1.01,0) -> 0 | Q6: =+P6*0.01 -> 0 | R6: =+IF(G6=$R$2,M6/1.1,0) -> 0 | S6: =+R6*0.1 -> 0 | T6: =+IF(G6=$T$2,M6/1.2,0) -> 0 | U6: =+T6*0.2 -> 0 | V6: =+N6+P6+R6+T6 -> 563.88 | W6: =+O6+Q6+S6+U6 -> 0
A7: 4 | C7: =+VLOOKUP(B7,'VERİ BANKASI'!M:N,2,0) -> #N/A | D7: YURTİÇİ SEYAHAT VE KONAKLAMA GİD. | E7: 1144 | F7: 46035 | H7: 195.99 | I7: OY **** 5805 / ŞAHSİ | J7: MESKUR | L7: =IF(OR(D7="ARAÇ YAKIT GİDERİ",D7="ARAÇ OTOPARK VE VALE GİDERLERİ",D7="ARAÇ TAMİR VE BAKIM GİDERLERİ"),H7*30/100,0)+(IF(D7="689 KANUNEN KABUL EDİLMEYEN GİD.",H7*1,0)) -> 0 | M7: =+H7-L7 -> 195.99 | N7: =+IF(G7=$N$2,M7,0) -> 195.99 | O7: =+N7*0/100 -> 0 | P7: =+IF(G7=$P$2,M7/1.01,0) -> 0 | Q7: =+P7*0.01 -> 0 | R7: =+IF(G7=$R$2,M7/1.1,0) -> 0 | S7: =+R7*0.1 -> 0 | T7: =+IF(G7=$T$2,M7/1.2,0) -> 0 | U7: =+T7*0.2 -> 0 | V7: =+N7+P7+R7+T7 -> 195.99 | W7: =+O7+Q7+S7+U7 -> 0
A8: 6 | C8: =+VLOOKUP(B8,'VERİ BANKASI'!M:N,2,0) -> #N/A | D8: YURTİÇİ SEYAHAT VE KONAKLAMA GİD. | E8: 926 | F8: 46035 | H8: 327.43 | I8: OY **** 5805 / ŞAHSİ | J8: MESKUR | L8: =IF(OR(D8="ARAÇ YAKIT GİDERİ",D8="ARAÇ OTOPARK VE VALE GİDERLERİ",D8="ARAÇ TAMİR VE BAKIM GİDERLERİ"),H8*30/100,0)+(IF(D8="689 KANUNEN KABUL EDİLMEYEN GİD.",H8*1,0)) -> 0 | M8: =+H8-L8 -> 327.43 | N8: =+IF(G8=$N$2,M8,0) -> 327.43 | O8: =+N8*0/100 -> 0 | P8: =+IF(G8=$P$2,M8/1.01,0) -> 0 | Q8: =+P8*0.01 -> 0 | R8: =+IF(G8=$R$2,M8/1.1,0) -> 0 | S8: =+R8*0.1 -> 0 | T8: =+IF(G8=$T$2,M8/1.2,0) -> 0 | U8: =+T8*0.2 -> 0 | V8: =+N8+P8+R8+T8 -> 327.43 | W8: =+O8+Q8+S8+U8 -> 0
A9: 7 | B9: 4810557424 | C9: =+VLOOKUP(B9,'VERİ BANKASI'!M:N,2,0) -> İSTANBUL ŞEHİR HATLARI TUR. TİC. A.Ş. | D9: YİYECEK-İÇECEK GİDERLERİ | E9: 52 | F9: 46033 | G9: 10 | H9: 15 | I9: OY **** 1585 / ŞAHSİ | J9: MESKUR | L9: =IF(OR(D9="ARAÇ YAKIT GİDERİ",D9="ARAÇ OTOPARK VE VALE GİDERLERİ",D9="ARAÇ TAMİR VE BAKIM GİDERLERİ"),H9*30/100,0)+(IF(D9="689 KANUNEN KABUL EDİLMEYEN GİD.",H9*1,0)) -> 0 | M9: =+H9-L9 -> 15 | N9: =+IF(G9=$N$2,M9,0) -> 0 | O9: =+N9*0/100 -> 0 | P9: =+IF(G9=$P$2,M9/1.01,0) -> 0 | Q9: =+P9*0.01 -> 0 | R9: =+IF(G9=$R$2,M9/1.1,0) -> 13.636364 | S9: =+R9*0.1 -> 1.3636364 | T9: =+IF(G9=$T$2,M9/1.2,0) -> 0 | U9: =+T9*0.2 -> 0 | V9: =+N9+P9+R9+T9 -> 13.636364 | W9: =+O9+Q9+S9+U9 -> 1.3636364
A10: 8 | C10: =+VLOOKUP(B10,'VERİ BANKASI'!M:N,2,0) -> #N/A | D10: YURTİÇİ SEYAHAT VE KONAKLAMA GİD. | E10: 1795 | F10: 46033 | H10: 687.09 | I10: OY **** 5805 / ŞAHSİ | J10: MESKUR | L10: =IF(OR(D10="ARAÇ YAKIT GİDERİ",D10="ARAÇ OTOPARK VE VALE GİDERLERİ",D10="ARAÇ TAMİR VE BAKIM GİDERLERİ"),H10*30/100,0)+(IF(D10="689 KANUNEN KABUL EDİLMEYEN GİD.",H10*1,0)) -> 0 | M10: =+H10-L10 -> 687.09 | N10: =+IF(G10=$N$2,M10,0) -> 687.09 | O10: =+N10*0/100 -> 0 | P10: =+IF(G10=$P$2,M10/1.01,0) -> 0 | Q10: =+P10*0.01 -> 0 | R10: =+IF(G10=$R$2,M10/1.1,0) -> 0 | S10: =+R10*0.1 -> 0 | T10: =+IF(G10=$T$2,M10/1.2,0) -> 0 | U10: =+T10*0.2 -> 0 | V10: =+N10+P10+R10+T10 -> 687.09 | W10: =+O10+Q10+S10+U10 -> 0
A11: 9 | B11: 7690007614 | C11: =+VLOOKUP(B11,'VERİ BANKASI'!M:N,2,0) -> SHELL PETROL A.Ş. | D11: YİYECEK-İÇECEK GİDERLERİ | E11: 65 | F11: 46039 | G11: 1 | H11: 155 | I11: OY **** 1038 / ŞAHSİ | J11: MESKUR | L11: =IF(OR(D11="ARAÇ YAKIT GİDERİ",D11="ARAÇ OTOPARK VE VALE GİDERLERİ",D11="ARAÇ TAMİR VE BAKIM GİDERLERİ"),H11*30/100,0)+(IF(D11="689 KANUNEN KABUL EDİLMEYEN GİD.",H11*1,0)) -> 0 | M11: =+H11-L11 -> 155 | N11: =+IF(G11=$N$2,M11,0) -> 0 | O11: =+N11*0/100 -> 0 | P11: =+IF(G11=$P$2,M11/1.01,0) -> 153.46535 | Q11: =+P11*0.01 -> 1.5346535 | R11: =+IF(G11=$R$2,M11/1.1,0) -> 0 | S11: =+R11*0.1 -> 0 | T11: =+IF(G11=$T$2,M11/1.2,0) -> 0 | U11: =+T11*0.2 -> 0 | V11: =+N11+P11+R11+T11 -> 153.46535 | W11: =+O11+Q11+S11+U11 -> 1.5346535
A12: 12 | B12: 7342092685 | C12: =+VLOOKUP(B12,'VERİ BANKASI'!M:N,2,0) -> RAZPOL PETROLCÜLÜK A.Ş. | D12: YİYECEK-İÇECEK GİDERLERİ | E12: 551 | F12: 46041 | G12: 1 | H12: 190 | I12: NAKİT / PARA | J12: MESKUR | L12: =IF(OR(D12="ARAÇ YAKIT GİDERİ",D12="ARAÇ OTOPARK VE VALE GİDERLERİ",D12="ARAÇ TAMİR VE BAKIM GİDERLERİ"),H12*30/100,0)+(IF(D12="689 KANUNEN KABUL EDİLMEYEN GİD.",H12*1,0)) -> 0 | M12: =+H12-L12 -> 190 | N12: =+IF(G12=$N$2,M12,0) -> 0 | O12: =+N12*0/100 -> 0 | P12: =+IF(G12=$P$2,M12/1.01,0) -> 188.11881 | Q12: =+P12*0.01 -> 1.8811881 | R12: =+IF(G12=$R$2,M12/1.1,0) -> 0 | S12: =+R12*0.1 -> 0 | T12: =+IF(G12=$T$2,M12/1.2,0) -> 0 | U12: =+T12*0.2 -> 0 | V12: =+N12+P12+R12+T12 -> 188.11881 | W12: =+O12+Q12+S12+U12 -> 1.8811881
A13: 14 | B13: 7290015043 | C13: =+VLOOKUP(B13,'VERİ BANKASI'!M:N,2,0) -> PETROL OFİSİ A.Ş. | D13: YİYECEK-İÇECEK GİDERLERİ | E13: 75 | F13: 46042 | G13: 10 | H13: 20 | I13: OY **** 5805 / ŞAHSİ | J13: MESKUR | L13: =IF(OR(D13="ARAÇ YAKIT GİDERİ",D13="ARAÇ OTOPARK VE VALE GİDERLERİ",D13="ARAÇ TAMİR VE BAKIM GİDERLERİ"),H13*30/100,0)+(IF(D13="689 KANUNEN KABUL EDİLMEYEN GİD.",H13*1,0)) -> 0 | M13: =+H13-L13 -> 20 | N13: =+IF(G13=$N$2,M13,0) -> 0 | O13: =+N13*0/100 -> 0 | P13: =+IF(G13=$P$2,M13/1.01,0) -> 0 | Q13: =+P13*0.01 -> 0 | R13: =+IF(G13=$R$2,M13/1.1,0) -> 18.181818 | S13: =+R13*0.1 -> 1.8181818 | T13: =+IF(G13=$T$2,M13/1.2,0) -> 0 | U13: =+T13*0.2 -> 0 | V13: =+N13+P13+R13+T13 -> 18.181818 | W13: =+O13+Q13+S13+U13 -> 1.8181818
A14: 15 | B14: 7290015043 | C14: =+VLOOKUP(B14,'VERİ BANKASI'!M:N,2,0) -> PETROL OFİSİ A.Ş. | D14: YİYECEK-İÇECEK GİDERLERİ | E14: 274 | F14: 46037 | G14: 10 | H14: 20 | I14: OY **** 5805 / ŞAHSİ | J14: MESKUR | L14: =IF(OR(D14="ARAÇ YAKIT GİDERİ",D14="ARAÇ OTOPARK VE VALE GİDERLERİ",D14="ARAÇ TAMİR VE BAKIM GİDERLERİ"),H14*30/100,0)+(IF(D14="689 KANUNEN KABUL EDİLMEYEN GİD.",H14*1,0)) -> 0 | M14: =+H14-L14 -> 20 | N14: =+IF(G14=$N$2,M14,0) -> 0 | O14: =+N14*0/100 -> 0 | P14: =+IF(G14=$P$2,M14/1.01,0) -> 0 | Q14: =+P14*0.01 -> 0 | R14: =+IF(G14=$R$2,M14/1.1,0) -> 18.181818 | S14: =+R14*0.1 -> 1.8181818 | T14: =+IF(G14=$T$2,M14/1.2,0) -> 0 | U14: =+T14*0.2 -> 0 | V14: =+N14+P14+R14+T14 -> 18.181818 | W14: =+O14+Q14+S14+U14 -> 1.8181818
A15: 16 | C15: =+VLOOKUP(B15,'VERİ BANKASI'!M:N,2,0) -> #N/A | J15: MESKUR | L15: =IF(OR(D15="ARAÇ YAKIT GİDERİ",D15="ARAÇ OTOPARK VE VALE GİDERLERİ",D15="ARAÇ TAMİR VE BAKIM GİDERLERİ"),H15*30/100,0)+(IF(D15="689 KANUNEN KABUL EDİLMEYEN GİD.",H15*1,0)) -> 0 | M15: =+H15-L15 -> 0 | N15: =+IF(G15=$N$2,M15,0) -> 0 | O15: =+N15*0/100 -> 0 | P15: =+IF(G15=$P$2,M15/1.01,0) -> 0 | Q15: =+P15*0.01 -> 0 | R15: =+IF(G15=$R$2,M15/1.1,0) -> 0 | S15: =+R15*0.1 -> 0 | T15: =+IF(G15=$T$2,M15/1.2,0) -> 0 | U15: =+T15*0.2 -> 0 | V15: =+N15+P15+R15+T15 -> 0 | W15: =+O15+Q15+S15+U15 -> 0
A16: 17 | C16: =+VLOOKUP(B16,'VERİ BANKASI'!M:N,2,0) -> #N/A | J16: MESKUR | L16: =IF(OR(D16="ARAÇ YAKIT GİDERİ",D16="ARAÇ OTOPARK VE VALE GİDERLERİ",D16="ARAÇ TAMİR VE BAKIM GİDERLERİ"),H16*30/100,0)+(IF(D16="689 KANUNEN KABUL EDİLMEYEN GİD.",H16*1,0)) -> 0 | M16: =+H16-L16 -> 0 | N16: =+IF(G16=$N$2,M16,0) -> 0 | O16: =+N16*0/100 -> 0 | P16: =+IF(G16=$P$2,M16/1.01,0) -> 0 | Q16: =+P16*0.01 -> 0 | R16: =+IF(G16=$R$2,M16/1.1,0) -> 0 | S16: =+R16*0.1 -> 0 | T16: =+IF(G16=$T$2,M16/1.2,0) -> 0 | U16: =+T16*0.2 -> 0 | V16: =+N16+P16+R16+T16 -> 0 | W16: =+O16+Q16+S16+U16 -> 0
A17: 18 | B17: 5270388270 | C17: =+VLOOKUP(B17,'VERİ BANKASI'!M:N,2,0) -> KASIMPAŞA SPOR KULÜBÜ DER.İKT.İŞL. | D17: ARAÇ OTOPARK VE VALE GİDERLERİ | E17: 71 | F17: 46036 | G17: 20 | H17: 310 | I17: NAKİT / PARA | J17: MESKUR | L17: =IF(OR(D17="ARAÇ YAKIT GİDERİ",D17="ARAÇ OTOPARK VE VALE GİDERLERİ",D17="ARAÇ TAMİR VE BAKIM GİDERLERİ"),H17*30/100,0)+(IF(D17="689 KANUNEN KABUL EDİLMEYEN GİD.",H17*1,0)) -> 93 | M17: =+H17-L17 -> 217 | N17: =+IF(G17=$N$2,M17,0) -> 0 | O17: =+N17*0/100 -> 0 | P17: =+IF(G17=$P$2,M17/1.01,0) -> 0 | Q17: =+P17*0.01 -> 0 | R17: =+IF(G17=$R$2,M17/1.1,0) -> 0 | S17: =+R17*0.1 -> 0 | T17: =+IF(G17=$T$2,M17/1.2,0) -> 180.83333 | U17: =+T17*0.2 -> 36.166667 | V17: =+N17+P17+R17+T17 -> 180.83333 | W17: =+O17+Q17+S17+U17 -> 36.166667
A18: 19 | C18: =+VLOOKUP(B18,'VERİ BANKASI'!M:N,2,0) -> #N/A | J18: MESKUR | L18: =IF(OR(D18="ARAÇ YAKIT GİDERİ",D18="ARAÇ OTOPARK VE VALE GİDERLERİ",D18="ARAÇ TAMİR VE BAKIM GİDERLERİ"),H18*30/100,0)+(IF(D18="689 KANUNEN KABUL EDİLMEYEN GİD.",H18*1,0)) -> 0 | M18: =+H18-L18 -> 0 | N18: =+IF(G18=$N$2,M18,0) -> 0 | O18: =+N18*0/100 -> 0 | P18: =+IF(G18=$P$2,M18/1.01,0) -> 0 | Q18: =+P18*0.01 -> 0 | R18: =+IF(G18=$R$2,M18/1.1,0) -> 0 | S18: =+R18*0.1 -> 0 | T18: =+IF(G18=$T$2,M18/1.2,0) -> 0 | U18: =+T18*0.2 -> 0 | V18: =+N18+P18+R18+T18 -> 0 | W18: =+O18+Q18+S18+U18 -> 0
A19: 20 | C19: =+VLOOKUP(B19,'VERİ BANKASI'!M:N,2,0) -> #N/A | J19: MESKUR | L19: =IF(OR(D19="ARAÇ YAKIT GİDERİ",D19="ARAÇ OTOPARK VE VALE GİDERLERİ",D19="ARAÇ TAMİR VE BAKIM GİDERLERİ"),H19*30/100,0)+(IF(D19="689 KANUNEN KABUL EDİLMEYEN GİD.",H19*1,0)) -> 0 | M19: =+H19-L19 -> 0 | N19: =+IF(G19=$N$2,M19,0) -> 0 | O19: =+N19*0/100 -> 0 | P19: =+IF(G19=$P$2,M19/1.01,0) -> 0 | Q19: =+P19*0.01 -> 0 | R19: =+IF(G19=$R$2,M19/1.1,0) -> 0 | S19: =+R19*0.1 -> 0 | T19: =+IF(G19=$T$2,M19/1.2,0) -> 0 | U19: =+T19*0.2 -> 0 | V19: =+N19+P19+R19+T19 -> 0 | W19: =+O19+Q19+S19+U19 -> 0
A20: 21 | C20: =+VLOOKUP(B20,'VERİ BANKASI'!M:N,2,0) -> #N/A | J20: MESKUR | L20: =IF(OR(D20="ARAÇ YAKIT GİDERİ",D20="ARAÇ OTOPARK VE VALE GİDERLERİ",D20="ARAÇ TAMİR VE BAKIM GİDERLERİ"),H20*30/100,0)+(IF(D20="689 KANUNEN KABUL EDİLMEYEN GİD.",H20*1,0)) -> 0 | M20: =+H20-L20 -> 0 | N20: =+IF(G20=$N$2,M20,0) -> 0 | O20: =+N20*0/100 -> 0 | P20: =+IF(G20=$P$2,M20/1.01,0) -> 0 | Q20: =+P20*0.01 -> 0 | R20: =+IF(G20=$R$2,M20/1.1,0) -> 0 | S20: =+R20*0.1 -> 0 | T20: =+IF(G20=$T$2,M20/1.2,0) -> 0 | U20: =+T20*0.2 -> 0 | V20: =+N20+P20+R20+T20 -> 0 | W20: =+O20+Q20+S20+U20 -> 0
A21: 22 | C21: =+VLOOKUP(B21,'VERİ BANKASI'!M:N,2,0) -> #N/A | J21: MESKUR | L21: =IF(OR(D21="ARAÇ YAKIT GİDERİ",D21="ARAÇ OTOPARK VE VALE GİDERLERİ",D21="ARAÇ TAMİR VE BAKIM GİDERLERİ"),H21*30/100,0)+(IF(D21="689 KANUNEN KABUL EDİLMEYEN GİD.",H21*1,0)) -> 0 | M21: =+H21-L21 -> 0 | N21: =+IF(G21=$N$2,M21,0) -> 0 | O21: =+N21*0/100 -> 0 | P21: =+IF(G21=$P$2,M21/1.01,0) -> 0 | Q21: =+P21*0.01 -> 0 | R21: =+IF(G21=$R$2,M21/1.1,0) -> 0 | S21: =+R21*0.1 -> 0 | T21: =+IF(G21=$T$2,M21/1.2,0) -> 0 | U21: =+T21*0.2 -> 0 | V21: =+N21+P21+R21+T21 -> 0 | W21: =+O21+Q21+S21+U21 -> 0
A22: 23 | C22: =+VLOOKUP(B22,'VERİ BANKASI'!M:N,2,0) -> #N/A | J22: MESKUR | L22: =IF(OR(D22="ARAÇ YAKIT GİDERİ",D22="ARAÇ OTOPARK VE VALE GİDERLERİ",D22="ARAÇ TAMİR VE BAKIM GİDERLERİ"),H22*30/100,0)+(IF(D22="689 KANUNEN KABUL EDİLMEYEN GİD.",H22*1,0)) -> 0 | M22: =+H22-L22 -> 0 | N22: =+IF(G22=$N$2,M22,0) -> 0 | O22: =+N22*0/100 -> 0 | P22: =+IF(G22=$P$2,M22/1.01,0) -> 0 | Q22: =+P22*0.01 -> 0 | R22: =+IF(G22=$R$2,M22/1.1,0) -> 0 | S22: =+R22*0.1 -> 0 | T22: =+IF(G22=$T$2,M22/1.2,0) -> 0 | U22: =+T22*0.2 -> 0 | V22: =+N22+P22+R22+T22 -> 0 | W22: =+O22+Q22+S22+U22 -> 0
A23: 24 | C23: =+VLOOKUP(B23,'VERİ BANKASI'!M:N,2,0) -> #N/A | J23: MESKUR | L23: =IF(OR(D23="ARAÇ YAKIT GİDERİ",D23="ARAÇ OTOPARK VE VALE GİDERLERİ",D23="ARAÇ TAMİR VE BAKIM GİDERLERİ"),H23*30/100,0)+(IF(D23="689 KANUNEN KABUL EDİLMEYEN GİD.",H23*1,0)) -> 0 | M23: =+H23-L23 -> 0 | N23: =+IF(G23=$N$2,M23,0) -> 0 | O23: =+N23*0/100 -> 0 | P23: =+IF(G23=$P$2,M23/1.01,0) -> 0 | Q23: =+P23*0.01 -> 0 | R23: =+IF(G23=$R$2,M23/1.1,0) -> 0 | S23: =+R23*0.1 -> 0 | T23: =+IF(G23=$T$2,M23/1.2,0) -> 0 | U23: =+T23*0.2 -> 0 | V23: =+N23+P23+R23+T23 -> 0 | W23: =+O23+Q23+S23+U23 -> 0
A24: 25 | C24: =+VLOOKUP(B24,'VERİ BANKASI'!M:N,2,0) -> #N/A | J24: MESKUR | L24: =IF(OR(D24="ARAÇ YAKIT GİDERİ",D24="ARAÇ OTOPARK VE VALE GİDERLERİ",D24="ARAÇ TAMİR VE BAKIM GİDERLERİ"),H24*30/100,0)+(IF(D24="689 KANUNEN KABUL EDİLMEYEN GİD.",H24*1,0)) -> 0 | M24: =+H24-L24 -> 0 | N24: =+IF(G24=$N$2,M24,0) -> 0 | O24: =+N24*0/100 -> 0 | P24: =+IF(G24=$P$2,M24/1.01,0) -> 0 | Q24: =+P24*0.01 -> 0 | R24: =+IF(G24=$R$2,M24/1.1,0) -> 0 | S24: =+R24*0.1 -> 0 | T24: =+IF(G24=$T$2,M24/1.2,0) -> 0 | U24: =+T24*0.2 -> 0 | V24: =+N24+P24+R24+T24 -> 0 | W24: =+O24+Q24+S24+U24 -> 0
A25: 26 | C25: =+VLOOKUP(B25,'VERİ BANKASI'!M:N,2,0) -> #N/A | J25: MESKUR | L25: =IF(OR(D25="ARAÇ YAKIT GİDERİ",D25="ARAÇ OTOPARK VE VALE GİDERLERİ",D25="ARAÇ TAMİR VE BAKIM GİDERLERİ"),H25*30/100,0)+(IF(D25="689 KANUNEN KABUL EDİLMEYEN GİD.",H25*1,0)) -> 0 | M25: =+H25-L25 -> 0 | N25: =+IF(G25=$N$2,M25,0) -> 0 | O25: =+N25*0/100 -> 0 | P25: =+IF(G25=$P$2,M25/1.01,0) -> 0 | Q25: =+P25*0.01 -> 0 | R25: =+IF(G25=$R$2,M25/1.1,0) -> 0 | S25: =+R25*0.1 -> 0 | T25: =+IF(G25=$T$2,M25/1.2,0) -> 0 | U25: =+T25*0.2 -> 0 | V25: =+N25+P25+R25+T25 -> 0 | W25: =+O25+Q25+S25+U25 -> 0
A26: 27 | C26: =+VLOOKUP(B26,'VERİ BANKASI'!M:N,2,0) -> #N/A | J26: MESKUR | L26: =IF(OR(D26="ARAÇ YAKIT GİDERİ",D26="ARAÇ OTOPARK VE VALE GİDERLERİ",D26="ARAÇ TAMİR VE BAKIM GİDERLERİ"),H26*30/100,0)+(IF(D26="689 KANUNEN KABUL EDİLMEYEN GİD.",H26*1,0)) -> 0 | M26: =+H26-L26 -> 0 | N26: =+IF(G26=$N$2,M26,0) -> 0 | O26: =+N26*0/100 -> 0 | P26: =+IF(G26=$P$2,M26/1.01,0) -> 0 | Q26: =+P26*0.01 -> 0 | R26: =+IF(G26=$R$2,M26/1.1,0) -> 0 | S26: =+R26*0.1 -> 0 | T26: =+IF(G26=$T$2,M26/1.2,0) -> 0 | U26: =+T26*0.2 -> 0 | V26: =+N26+P26+R26+T26 -> 0 | W26: =+O26+Q26+S26+U26 -> 0
A27: 28 | C27: =+VLOOKUP(B27,'VERİ BANKASI'!M:N,2,0) -> #N/A | J27: MESKUR | L27: =IF(OR(D27="ARAÇ YAKIT GİDERİ",D27="ARAÇ OTOPARK VE VALE GİDERLERİ",D27="ARAÇ TAMİR VE BAKIM GİDERLERİ"),H27*30/100,0)+(IF(D27="689 KANUNEN KABUL EDİLMEYEN GİD.",H27*1,0)) -> 0 | M27: =+H27-L27 -> 0 | N27: =+IF(G27=$N$2,M27,0) -> 0 | O27: =+N27*0/100 -> 0 | P27: =+IF(G27=$P$2,M27/1.01,0) -> 0 | Q27: =+P27*0.01 -> 0 | R27: =+IF(G27=$R$2,M27/1.1,0) -> 0 | S27: =+R27*0.1 -> 0 | T27: =+IF(G27=$T$2,M27/1.2,0) -> 0 | U27: =+T27*0.2 -> 0 | V27: =+N27+P27+R27+T27 -> 0 | W27: =+O27+Q27+S27+U27 -> 0
A28: 29 | C28: =+VLOOKUP(B28,'VERİ BANKASI'!M:N,2,0) -> #N/A | J28: MESKUR | L28: =IF(OR(D28="ARAÇ YAKIT GİDERİ",D28="ARAÇ OTOPARK VE VALE GİDERLERİ",D28="ARAÇ TAMİR VE BAKIM GİDERLERİ"),H28*30/100,0)+(IF(D28="689 KANUNEN KABUL EDİLMEYEN GİD.",H28*1,0)) -> 0 | M28: =+H28-L28 -> 0 | N28: =+IF(G28=$N$2,M28,0) -> 0 | O28: =+N28*0/100 -> 0 | P28: =+IF(G28=$P$2,M28/1.01,0) -> 0 | Q28: =+P28*0.01 -> 0 | R28: =+IF(G28=$R$2,M28/1.1,0) -> 0 | S28: =+R28*0.1 -> 0 | T28: =+IF(G28=$T$2,M28/1.2,0) -> 0 | U28: =+T28*0.2 -> 0 | V28: =+N28+P28+R28+T28 -> 0 | W28: =+O28+Q28+S28+U28 -> 0
A29: 30 | C29: =+VLOOKUP(B29,'VERİ BANKASI'!M:N,2,0) -> #N/A | J29: MESKUR | L29: =IF(OR(D29="ARAÇ YAKIT GİDERİ",D29="ARAÇ OTOPARK VE VALE GİDERLERİ",D29="ARAÇ TAMİR VE BAKIM GİDERLERİ"),H29*30/100,0)+(IF(D29="689 KANUNEN KABUL EDİLMEYEN GİD.",H29*1,0)) -> 0 | M29: =+H29-L29 -> 0 | N29: =+IF(G29=$N$2,M29,0) -> 0 | O29: =+N29*0/100 -> 0 | P29: =+IF(G29=$P$2,M29/1.01,0) -> 0 | Q29: =+P29*0.01 -> 0 | R29: =+IF(G29=$R$2,M29/1.1,0) -> 0 | S29: =+R29*0.1 -> 0 | T29: =+IF(G29=$T$2,M29/1.2,0) -> 0 | U29: =+T29*0.2 -> 0 | V29: =+N29+P29+R29+T29 -> 0 | W29: =+O29+Q29+S29+U29 -> 0
... A50: 51 | C50: =+VLOOKUP(B50,'VERİ BANKASI'!M:N,2,0) -> #N/A | J50: MESKUR | L50: =IF(OR(D50="ARAÇ YAKIT GİDERİ",D50="ARAÇ OTOPARK VE VALE GİDERLERİ",D50="ARAÇ TAMİR VE BAKIM GİDERLERİ"),H50*30/100,0)+(IF(D50="689 KANUNEN KABUL EDİLMEYEN GİD.",H50*1,0)) -> 0 | M50: =+H50-L50 -> 0 | N50: =+IF(G50=$N$2,M50,0) -> 0 | O50: =+N50*0/100 -> 0 | P50: =+IF(G50=$P$2,M50/1.01,0) -> 0 | Q50: =+P50*0.01 -> 0 | R50: =+IF(G50=$R$2,M50/1.1,0) -> 0 | S50: =+R50*0.1 -> 0 | T50: =+IF(G50=$T$2,M50/1.2,0) -> 0 | U50: =+T50*0.2 -> 0 | V50: =+N50+P50+R50+T50 -> 0 | W50: =+O50+Q50+S50+U50 -> 0
C53: TOPLAMLAR | H53: =SUBTOTAL(9,H4:H52) -> 6159.39 | L53: =+SUBTOTAL(9,L4:L51) -> 93 | M53: =+SUBTOTAL(9,M4:M51) -> 6066.39 | N53: =+SUBTOTAL(9,N4:N51) -> 1774.39 | O53: =+SUBTOTAL(9,O4:O51) -> 0 | P53: =+SUBTOTAL(9,P4:P51) -> 341.58416 | Q53: =+SUBTOTAL(9,Q4:Q51) -> 3.4158416 | R53: =+SUBTOTAL(9,R4:R51) -> 3390.9091 | S53: =+SUBTOTAL(9,S4:S51) -> 339.09091 | ... W53: =+SUBTOTAL(9,W4:W51) -> 378.67342
A55: S.N. | B55: MASRAF DAĞILIMI | C55: MATRAH %0 | D55: KDV %0 | E55: MATRAH %1 | F55: KDV %1 | G55: MATRAH %10 | H55: KDV %10 | I55: MATRAH%20 | J55: KDV%20 | K55: KKEG | L55: Toplam | M55: BELGE ADETİ | O55: PER. ADI | P55: ONUR YILDIRIM | T55: ALINAN AVANS TOPLAMI | W55: 0
A56: 1 | B56: =+'VERİ BANKASI'!B2 -> ARAÇ YAKIT GİDERİ | C56: =SUMIF($D$4:$D$51,B56,$N$4:$N$51) -> 0 | D56: =SUMIF($D$4:$D$51,B56,$O$4:$O$51) -> 0 | E56: =SUMIF($D$4:$D$51,B56,$P$4:$P$51) -> 0 | F56: =SUMIF($D$4:$D$51,B56,$Q$4:$Q$51) -> 0 | G56: =SUMIF($D$4:$D$51,B56,$R$4:$R$51) -> 0 | H56: =SUMIF($D$4:$D$51,B56,$S$4:$S$51) -> 0 | I56: =SUMIF($D$4:$D$51,B56,$T$4:$T$51) -> 0 | J56: =SUMIF($D$4:$D$51,B56,$U$4:$U$51) -> 0 | K56: =SUMIF($D$4:$D$51,B56,$L$4:$L$51) -> 0 | L56: =+SUM(C56:K56) -> 0 | M56: =+COUNTIF($D$4:D49,B56) -> 0 | O56: ŞİRKET | P56: MESKUR KURUMSAL A.Ş.
A57: 2 | B57: =+'VERİ BANKASI'!B3 -> ARAÇ OTOPARK VE VALE GİDERLERİ | C57: =SUMIF($D$4:$D$51,B57,$N$4:$N$51) -> 0 | D57: =SUMIF($D$4:$D$51,B57,$O$4:$O$51) -> 0 | E57: =SUMIF($D$4:$D$51,B57,$P$4:$P$51) -> 0 | F57: =SUMIF($D$4:$D$51,B57,$Q$4:$Q$51) -> 0 | G57: =SUMIF($D$4:$D$51,B57,$R$4:$R$51) -> 0 | H57: =SUMIF($D$4:$D$51,B57,$S$4:$S$51) -> 0 | I57: =SUMIF($D$4:$D$51,B57,$T$4:$T$51) -> 180.83333 | J57: =SUMIF($D$4:$D$51,B57,$U$4:$U$51) -> 36.166667 | K57: =SUMIF($D$4:$D$51,B57,$L$4:$L$51) -> 93 | L57: =+SUM(C57:K57) -> 310 | M57: =+COUNTIF($D$4:D51,B57) -> 1 | O57: İŞYERİ | P57: İSTANBUL | T57: HARCAMA TOPLAMA | W57: =+L53+V53+W53 -> 6159.39
A58: 3 | B58: =+'VERİ BANKASI'!B4 -> ARAÇ TAMİR VE BAKIM GİDERLERİ | C58: =SUMIF($D$4:$D$51,B58,$N$4:$N$51) -> 0 | D58: =SUMIF($D$4:$D$51,B58,$O$4:$O$51) -> 0 | E58: =SUMIF($D$4:$D$51,B58,$P$4:$P$51) -> 0 | F58: =SUMIF($D$4:$D$51,B58,$Q$4:$Q$51) -> 0 | G58: =SUMIF($D$4:$D$51,B58,$R$4:$R$51) -> 0 | H58: =SUMIF($D$4:$D$51,B58,$S$4:$S$51) -> 0 | I58: =SUMIF($D$4:$D$51,B58,$T$4:$T$51) -> 0 | J58: =SUMIF($D$4:$D$51,B58,$U$4:$U$51) -> 0 | K58: =SUMIF($D$4:$D$51,B58,$L$4:$L$51) -> 0 | L58: =+SUM(C58:K58) -> 0 | M58: =+COUNTIF($D$4:D52,B58) -> 0 | O58: YIL | P58: 2025
A59: 4 | B59: =+'VERİ BANKASI'!B5 -> MUTFAK YİYECEK VE İÇECEK GİDERLERİ | C59: =SUMIF($D$4:$D$51,B59,$N$4:$N$51) -> 0 | D59: =SUMIF($D$4:$D$51,B59,$O$4:$O$51) -> 0 | E59: =SUMIF($D$4:$D$51,B59,$P$4:$P$51) -> 0 | F59: =SUMIF($D$4:$D$51,B59,$Q$4:$Q$51) -> 0 | G59: =SUMIF($D$4:$D$51,B59,$R$4:$R$51) -> 0 | H59: =SUMIF($D$4:$D$51,B59,$S$4:$S$51) -> 0 | I59: =SUMIF($D$4:$D$51,B59,$T$4:$T$51) -> 0 | J59: =SUMIF($D$4:$D$51,B59,$U$4:$U$51) -> 0 | K59: =SUMIF($D$4:$D$51,B59,$L$4:$L$51) -> 0 | L59: =+SUM(C59:K59) -> 0 | M59: =+COUNTIF($D$4:D53,B59) -> 0 | O59: AY | P59: EKİM | T59: FARK | W59: =+W55-W57 -> -6159.39
A60: 5 | B60: =+'VERİ BANKASI'!B6 -> MUTFAK SARF MALZEME GİDERLERİ | C60: =SUMIF($D$4:$D$51,B60,$N$4:$N$51) -> 0 | D60: =SUMIF($D$4:$D$51,B60,$O$4:$O$51) -> 0 | E60: =SUMIF($D$4:$D$51,B60,$P$4:$P$51) -> 0 | F60: =SUMIF($D$4:$D$51,B60,$Q$4:$Q$51) -> 0 | G60: =SUMIF($D$4:$D$51,B60,$R$4:$R$51) -> 0 | H60: =SUMIF($D$4:$D$51,B60,$S$4:$S$51) -> 0 | I60: =SUMIF($D$4:$D$51,B60,$T$4:$T$51) -> 0 | J60: =SUMIF($D$4:$D$51,B60,$U$4:$U$51) -> 0 | K60: =SUMIF($D$4:$D$51,B60,$L$4:$L$51) -> 0 | L60: =+SUM(C60:K60) -> 0 | M60: =+COUNTIF($D$4:D54,B60) -> 0 | O60: GÜN | P60: 1-10 GÜN
A61: 6 | B61: =+'VERİ BANKASI'!B7 -> YİYECEK-İÇECEK GİDERLERİ | C61: =SUMIF($D$4:$D$51,B61,$N$4:$N$51) -> 0 | D61: =SUMIF($D$4:$D$51,B61,$O$4:$O$51) -> 0 | E61: =SUMIF($D$4:$D$51,B61,$P$4:$P$51) -> 341.58416 | F61: =SUMIF($D$4:$D$51,B61,$Q$4:$Q$51) -> 3.4158416 | G61: =SUMIF($D$4:$D$51,B61,$R$4:$R$51) -> 3390.9091 | H61: =SUMIF($D$4:$D$51,B61,$S$4:$S$51) -> 339.09091 | I61: =SUMIF($D$4:$D$51,B61,$T$4:$T$51) -> 0 | J61: =SUMIF($D$4:$D$51,B61,$U$4:$U$51) -> 0 | K61: =SUMIF($D$4:$D$51,B61,$L$4:$L$51) -> 0 | L61: =+SUM(C61:K61) -> 4075 | M61: =+COUNTIF($D$4:D55,B61) -> 7
A62: 7 | B62: =+'VERİ BANKASI'!B8 -> TEMSİL İKRAM VE YEMEK GİDERLERİ | C62: =SUMIF($D$4:$D$51,B62,$N$4:$N$51) -> 0 | D62: =SUMIF($D$4:$D$51,B62,$O$4:$O$51) -> 0 | E62: =SUMIF($D$4:$D$51,B62,$P$4:$P$51) -> 0 | F62: =SUMIF($D$4:$D$51,B62,$Q$4:$Q$51) -> 0 | G62: =SUMIF($D$4:$D$51,B62,$R$4:$R$51) -> 0 | H62: =SUMIF($D$4:$D$51,B62,$S$4:$S$51) -> 0 | I62: =SUMIF($D$4:$D$51,B62,$T$4:$T$51) -> 0 | J62: =SUMIF($D$4:$D$51,B62,$U$4:$U$51) -> 0 | K62: =SUMIF($D$4:$D$51,B62,$L$4:$L$51) -> 0 | L62: =+SUM(C62:K62) -> 0 | M62: =+COUNTIF($D$4:D55,B62) -> 0
A63: 8 | B63: =+'VERİ BANKASI'!B9 -> OFİS MAKİNA TAM.BAK.VE SARF MALZ. GİD. | C63: =SUMIF($D$4:$D$51,B63,$N$4:$N$51) -> 0 | D63: =SUMIF($D$4:$D$51,B63,$O$4:$O$51) -> 0 | E63: =SUMIF($D$4:$D$51,B63,$P$4:$P$51) -> 0 | F63: =SUMIF($D$4:$D$51,B63,$Q$4:$Q$51) -> 0 | G63: =SUMIF($D$4:$D$51,B63,$R$4:$R$51) -> 0 | H63: =SUMIF($D$4:$D$51,B63,$S$4:$S$51) -> 0 | I63: =SUMIF($D$4:$D$51,B63,$T$4:$T$51) -> 0 | J63: =SUMIF($D$4:$D$51,B63,$U$4:$U$51) -> 0 | K63: =SUMIF($D$4:$D$51,B63,$L$4:$L$51) -> 0 | L63: =+SUM(C63:K63) -> 0 | M63: =+COUNTIF($D$4:D56,B63) -> 0 | O63: PERSONEL | T63: ONAY MAKAMI
...

Sheet 01.AY O.Y. (01-10 ARASI) 2026
A1: MASRAF LİSTESİ
A2: BELGE DÜZENLEME TARİHİ | D2: =+TODAY() -> 46127 | E2: BELGEYE AİT BİLGİLER | H2: TOPLAM: | I2: =SUBTOTAL(9,H4:H52) -> 952.95 | N2: 0 | P2: 1 | R2: 10 | T2: 20 | V2: GENEL TOPLAMLAR
A3: S.N. | B3: BEL. AL. FİRMA ADI / UNVANI V.N. | C3: BELGENİN ALINDIĞI FİRMA ADI / UNVANI | D3: MASRAF TÜRÜ | E3: FATURA FİŞ NO | F3: BELGE TARİHİ | G3: KDV ORANI ( % … ) | H3: FİŞ GENEL TOPLAMI | I3: ÖDEME TÜRÜ | J3: MASRAF MERKEZİ | K3: ARAÇ PLAKA NO | L3: KKEG | M3: NET MATRAH | N3: MATRAH | O3: KDV | P3: MATRAH | Q3: KDV | R3: MATRAH | S3: KDV | T3: MATRAH | U3: KDV | V3: MATRAH TOPLAMI | W3: KDV TOPLAMI
A4: 1 | C4: =+VLOOKUP(B4,'VERİ BANKASI'!M:N,2,0) -> #N/A | D4: YURTİÇİ SEYAHAT VE KONAKLAMA GİD. | E4: 1 | F4: 46031 | H4: 192.95 | I4: OY **** 5805 / ŞAHSİ | J4: MESKUR | L4: =IF(OR(D4="ARAÇ YAKIT GİDERİ",D4="ARAÇ OTOPARK VE VALE GİDERLERİ",D4="ARAÇ TAMİR VE BAKIM GİDERLERİ"),H4*30/100,0)+(IF(D4="689 KANUNEN KABUL EDİLMEYEN GİD.",H4*1,0)) -> 0 | M4: =+H4-L4 -> 192.95 | N4: =+IF(G4=$N$2,M4,0) -> 192.95 | O4: =+N4*0/100 -> 0 | P4: =+IF(G4=$P$2,M4/1.01,0) -> 0 | Q4: =+P4*0.01 -> 0 | R4: =+IF(G4=$R$2,M4/1.1,0) -> 0 | S4: =+R4*0.1 -> 0 | T4: =+IF(G4=$T$2,M4/1.2,0) -> 0 | U4: =+T4*0.2 -> 0 | V4: =+N4+P4+R4+T4 -> 192.95 | W4: =+O4+Q4+S4+U4 -> 0
A5: 2 | B5: 4810557424 | C5: =+VLOOKUP(B5,'VERİ BANKASI'!M:N,2,0) -> İSTANBUL ŞEHİR HATLARI TUR. TİC. A.Ş. | D5: YİYECEK-İÇECEK GİDERLERİ | E5: 36 | F5: 46032 | G5: 10 | H5: 15 | I5: OY **** 5805 / ŞAHSİ | J5: MESKUR | L5: =IF(OR(D5="ARAÇ YAKIT GİDERİ",D5="ARAÇ OTOPARK VE VALE GİDERLERİ",D5="ARAÇ TAMİR VE BAKIM GİDERLERİ"),H5*30/100,0)+(IF(D5="689 KANUNEN KABUL EDİLMEYEN GİD.",H5*1,0)) -> 0 | M5: =+H5-L5 -> 15 | N5: =+IF(G5=$N$2,M5,0) -> 0 | O5: =+N5*0/100 -> 0 | P5: =+IF(G5=$P$2,M5/1.01,0) -> 0 | Q5: =+P5*0.01 -> 0 | R5: =+IF(G5=$R$2,M5/1.1,0) -> 13.636364 | S5: =+R5*0.1 -> 1.3636364 | T5: =+IF(G5=$T$2,M5/1.2,0) -> 0 | U5: =+T5*0.2 -> 0 | V5: =+N5+P5+R5+T5 -> 13.636364 | W5: =+O5+Q5+S5+U5 -> 1.3636364
A6: 3 | B6: 0690344813 | C6: =+VLOOKUP(B6,'VERİ BANKASI'!M:N,2,0) -> FUSKA - ANKA GIDA LTD. ŞTİ. | D6: YİYECEK-İÇECEK GİDERLERİ | E6: 21 | F6: 46032 | G6: 10 | H6: 200 | I6: OY **** 5805 / ŞAHSİ | J6: MESKUR | L6: =IF(OR(D6="ARAÇ YAKIT GİDERİ",D6="ARAÇ OTOPARK VE VALE GİDERLERİ",D6="ARAÇ TAMİR VE BAKIM GİDERLERİ"),H6*30/100,0)+(IF(D6="689 KANUNEN KABUL EDİLMEYEN GİD.",H6*1,0)) -> 0 | M6: =+H6-L6 -> 200 | N6: =+IF(G6=$N$2,M6,0) -> 0 | O6: =+N6*0/100 -> 0 | P6: =+IF(G6=$P$2,M6/1.01,0) -> 0 | Q6: =+P6*0.01 -> 0 | R6: =+IF(G6=$R$2,M6/1.1,0) -> 181.81818 | S6: =+R6*0.1 -> 18.181818 | T6: =+IF(G6=$T$2,M6/1.2,0) -> 0 | U6: =+T6*0.2 -> 0 | V6: =+N6+P6+R6+T6 -> 181.81818 | W6: =+O6+Q6+S6+U6 -> 18.181818
A7: 4 | B7: 7690007614 | C7: =+VLOOKUP(B7,'VERİ BANKASI'!M:N,2,0) -> SHELL PETROL A.Ş. | D7: YİYECEK-İÇECEK GİDERLERİ | E7: 45 | F7: 46028 | G7: 1 | H7: 90 | I7: OY **** 1038 / ŞAHSİ | J7: MESKUR | L7: =IF(OR(D7="ARAÇ YAKIT GİDERİ",D7="ARAÇ OTOPARK VE VALE GİDERLERİ",D7="ARAÇ TAMİR VE BAKIM GİDERLERİ"),H7*30/100,0)+(IF(D7="689 KANUNEN KABUL EDİLMEYEN GİD.",H7*1,0)) -> 0 | M7: =+H7-L7 -> 90 | N7: =+IF(G7=$N$2,M7,0) -> 0 | O7: =+N7*0/100 -> 0 | P7: =+IF(G7=$P$2,M7/1.01,0) -> 89.108911 | Q7: =+P7*0.01 -> 0.89108911 | R7: =+IF(G7=$R$2,M7/1.1,0) -> 0 | S7: =+R7*0.1 -> 0 | T7: =+IF(G7=$T$2,M7/1.2,0) -> 0 | U7: =+T7*0.2 -> 0 | V7: =+N7+P7+R7+T7 -> 89.108911 | W7: =+O7+Q7+S7+U7 -> 0.89108911
A8: 6 | B8: 4610399686 | C8: =+VLOOKUP(B8,'VERİ BANKASI'!M:N,2,0) -> HELVACILAR GIDA LTD. ŞTİ. | D8: YİYECEK-İÇECEK GİDERLERİ | E8: 109 | F8: 46032 | G8: 1 | H8: 395 | I8: OY **** 5805 / ŞAHSİ | J8: MESKUR | L8: =IF(OR(D8="ARAÇ YAKIT GİDERİ",D8="ARAÇ OTOPARK VE VALE GİDERLERİ",D8="ARAÇ TAMİR VE BAKIM GİDERLERİ"),H8*30/100,0)+(IF(D8="689 KANUNEN KABUL EDİLMEYEN GİD.",H8*1,0)) -> 0 | M8: =+H8-L8 -> 395 | N8: =+IF(G8=$N$2,M8,0) -> 0 | O8: =+N8*0/100 -> 0 | P8: =+IF(G8=$P$2,M8/1.01,0) -> 391.08911 | Q8: =+P8*0.01 -> 3.9108911 | R8: =+IF(G8=$R$2,M8/1.1,0) -> 0 | S8: =+R8*0.1 -> 0 | T8: =+IF(G8=$T$2,M8/1.2,0) -> 0 | U8: =+T8*0.2 -> 0 | V8: =+N8+P8+R8+T8 -> 391.08911 | W8: =+O8+Q8+S8+U8 -> 3.9108911
A9: 7 | B9: 7290015043 | C9: =+VLOOKUP(B9,'VERİ BANKASI'!M:N,2,0) -> PETROL OFİSİ A.Ş. | D9: YİYECEK-İÇECEK GİDERLERİ | E9: 292 | F9: 46031 | G9: 10 | H9: 20 | I9: OY **** 5805 / ŞAHSİ | J9: MESKUR | L9: =IF(OR(D9="ARAÇ YAKIT GİDERİ",D9="ARAÇ OTOPARK VE VALE GİDERLERİ",D9="ARAÇ TAMİR VE BAKIM GİDERLERİ"),H9*30/100,0)+(IF(D9="689 KANUNEN KABUL EDİLMEYEN GİD.",H9*1,0)) -> 0 | M9: =+H9-L9 -> 20 | N9: =+IF(G9=$N$2,M9,0) -> 0 | O9: =+N9*0/100 -> 0 | P9: =+IF(G9=$P$2,M9/1.01,0) -> 0 | Q9: =+P9*0.01 -> 0 | R9: =+IF(G9=$R$2,M9/1.1,0) -> 18.181818 | S9: =+R9*0.1 -> 1.8181818 | T9: =+IF(G9=$T$2,M9/1.2,0) -> 0 | U9: =+T9*0.2 -> 0 | V9: =+N9+P9+R9+T9 -> 18.181818 | W9: =+O9+Q9+S9+U9 -> 1.8181818
A10: 8 | B10: 7290015043 | C10: =+VLOOKUP(B10,'VERİ BANKASI'!M:N,2,0) -> PETROL OFİSİ A.Ş. | D10: YİYECEK-İÇECEK GİDERLERİ | E10: 280 | F10: 46024 | G10: 10 | H10: 20 | I10: OY **** 2023 / ŞAHSİ | J10: MESKUR | L10: =IF(OR(D10="ARAÇ YAKIT GİDERİ",D10="ARAÇ OTOPARK VE VALE GİDERLERİ",D10="ARAÇ TAMİR VE BAKIM GİDERLERİ"),H10*30/100,0)+(IF(D10="689 KANUNEN KABUL EDİLMEYEN GİD.",H10*1,0)) -> 0 | M10: =+H10-L10 -> 20 | N10: =+IF(G10=$N$2,M10,0) -> 0 | O10: =+N10*0/100 -> 0 | P10: =+IF(G10=$P$2,M10/1.01,0) -> 0 | Q10: =+P10*0.01 -> 0 | R10: =+IF(G10=$R$2,M10/1.1,0) -> 18.181818 | S10: =+R10*0.1 -> 1.8181818 | T10: =+IF(G10=$T$2,M10/1.2,0) -> 0 | U10: =+T10*0.2 -> 0 | V10: =+N10+P10+R10+T10 -> 18.181818 | W10: =+O10+Q10+S10+U10 -> 1.8181818
A11: 9 | B11: 7290015043 | C11: =+VLOOKUP(B11,'VERİ BANKASI'!M:N,2,0) -> PETROL OFİSİ A.Ş. | D11: YİYECEK-İÇECEK GİDERLERİ | E11: 130 | F11: 46030 | G11: 10 | H11: 20 | I11: OY **** 2023 / ŞAHSİ | J11: MESKUR | L11: =IF(OR(D11="ARAÇ YAKIT GİDERİ",D11="ARAÇ OTOPARK VE VALE GİDERLERİ",D11="ARAÇ TAMİR VE BAKIM GİDERLERİ"),H11*30/100,0)+(IF(D11="689 KANUNEN KABUL EDİLMEYEN GİD.",H11*1,0)) -> 0 | M11: =+H11-L11 -> 20 | N11: =+IF(G11=$N$2,M11,0) -> 0 | O11: =+N11*0/100 -> 0 | P11: =+IF(G11=$P$2,M11/1.01,0) -> 0 | Q11: =+P11*0.01 -> 0 | R11: =+IF(G11=$R$2,M11/1.1,0) -> 18.181818 | S11: =+R11*0.1 -> 1.8181818 | T11: =+IF(G11=$T$2,M11/1.2,0) -> 0 | U11: =+T11*0.2 -> 0 | V11: =+N11+P11+R11+T11 -> 18.181818 | W11: =+O11+Q11+S11+U11 -> 1.8181818
A12: 12 | C12: =+VLOOKUP(B12,'VERİ BANKASI'!M:N,2,0) -> #N/A | J12: MESKUR | L12: =IF(OR(D12="ARAÇ YAKIT GİDERİ",D12="ARAÇ OTOPARK VE VALE GİDERLERİ",D12="ARAÇ TAMİR VE BAKIM GİDERLERİ"),H12*30/100,0)+(IF(D12="689 KANUNEN KABUL EDİLMEYEN GİD.",H12*1,0)) -> 0 | M12: =+H12-L12 -> 0 | N12: =+IF(G12=$N$2,M12,0) -> 0 | O12: =+N12*0/100 -> 0 | P12: =+IF(G12=$P$2,M12/1.01,0) -> 0 | Q12: =+P12*0.01 -> 0 | R12: =+IF(G12=$R$2,M12/1.1,0) -> 0 | S12: =+R12*0.1 -> 0 | T12: =+IF(G12=$T$2,M12/1.2,0) -> 0 | U12: =+T12*0.2 -> 0 | V12: =+N12+P12+R12+T12 -> 0 | W12: =+O12+Q12+S12+U12 -> 0
A13: 14 | C13: =+VLOOKUP(B13,'VERİ BANKASI'!M:N,2,0) -> #N/A | J13: MESKUR | L13: =IF(OR(D13="ARAÇ YAKIT GİDERİ",D13="ARAÇ OTOPARK VE VALE GİDERLERİ",D13="ARAÇ TAMİR VE BAKIM GİDERLERİ"),H13*30/100,0)+(IF(D13="689 KANUNEN KABUL EDİLMEYEN GİD.",H13*1,0)) -> 0 | M13: =+H13-L13 -> 0 | N13: =+IF(G13=$N$2,M13,0) -> 0 | O13: =+N13*0/100 -> 0 | P13: =+IF(G13=$P$2,M13/1.01,0) -> 0 | Q13: =+P13*0.01 -> 0 | R13: =+IF(G13=$R$2,M13/1.1,0) -> 0 | S13: =+R13*0.1 -> 0 | T13: =+IF(G13=$T$2,M13/1.2,0) -> 0 | U13: =+T13*0.2 -> 0 | V13: =+N13+P13+R13+T13 -> 0 | W13: =+O13+Q13+S13+U13 -> 0
A14: 15 | C14: =+VLOOKUP(B14,'VERİ BANKASI'!M:N,2,0) -> #N/A | J14: MESKUR | L14: =IF(OR(D14="ARAÇ YAKIT GİDERİ",D14="ARAÇ OTOPARK VE VALE GİDERLERİ",D14="ARAÇ TAMİR VE BAKIM GİDERLERİ"),H14*30/100,0)+(IF(D14="689 KANUNEN KABUL EDİLMEYEN GİD.",H14*1,0)) -> 0 | M14: =+H14-L14 -> 0 | N14: =+IF(G14=$N$2,M14,0) -> 0 | O14: =+N14*0/100 -> 0 | P14: =+IF(G14=$P$2,M14/1.01,0) -> 0 | Q14: =+P14*0.01 -> 0 | R14: =+IF(G14=$R$2,M14/1.1,0) -> 0 | S14: =+R14*0.1 -> 0 | T14: =+IF(G14=$T$2,M14/1.2,0) -> 0 | U14: =+T14*0.2 -> 0 | V14: =+N14+P14+R14+T14 -> 0 | W14: =+O14+Q14+S14+U14 -> 0
